Workbook

Sheet 入力シート
B2: 被相続人
B4: 住居表示
C5: 土地
C6: 所在 | D6: 地番 | F6: 地目 | G6: 地積 | H6: 住所 | I6: 氏名 | J6: 登記原因 | K6: 現住所
A7: 1 | B7: 申請地 | C7: =+#REF! -> #REF! | D7: =+#REF! -> #REF! | E7: =CONCATENATE(C7,D7) -> #REF! | F7: =+#REF! -> #REF! | G7: =+#REF! -> #REF! | H7: =+#REF! -> #REF! | I7: =+#REF! -> #REF! | J7: =+#REF! -> #REF!
A8: 2 | B8: 隣接地 | C8: =+#REF! -> #REF! | D8: =+#REF! -> #REF! | E8: =CONCATENATE(C8,D8) -> #REF! | F8: =+#REF! -> #REF! | G8: =+#REF! -> #REF! | H8: =+#REF! -> #REF! | I8: =+#REF! -> #REF! | J8: =+#REF! -> #REF!
A9: 3 | B9: 隣接地 | C9: =+#REF! -> #REF! | D9: =+#REF! -> #REF! | E9: =CONCATENATE(C9,D9) -> #REF! | F9: =+#REF! -> #REF! | G9: =+#REF! -> #REF! | H9: =+#REF! -> #REF! | I9: =+#REF! -> #REF! | J9: =+#REF! -> #REF!
A10: 4 | B10: 隣接地 | C10: =+#REF! -> #REF! | D10: =+#REF! -> #REF! | E10: =CONCATENATE(C10,D10) -> #REF! | F10: =+#REF! -> #REF! | G10: =+#REF! -> #REF! | H10: =+#REF! -> #REF! | I10: =+#REF! -> #REF! | J10: =+#REF! -> #REF!
A11: 5 | B11: 隣接地 | C11: =+#REF! -> #REF! | D11: =+#REF! -> #REF! | E11: =CONCATENATE(C11,D11) -> #REF! | F11: =+#REF! -> #REF! | G11: =+#REF! -> #REF! | H11: =+#REF! -> #REF! | I11: =+#REF! -> #REF! | J11: =+#REF! -> #REF!
A12: 6 | B12: 隣接地 | C12: =+#REF! -> #REF! | D12: =+#REF! -> #REF! | E12: =CONCATENATE(C12,D12) -> #REF! | F12: =+#REF! -> #REF! | G12: =+#REF! -> #REF! | H12: =+#REF! -> #REF! | I12: =+#REF! -> #REF! | J12: =+#REF! -> #REF!
A13: 7
A14: 8
A15: 9
A16: 10
A17: 11
A18: 12
A19: 13
A20: 14
A21: 15
A22: 16
A23: 17
A24: 18
... A28: 22

Sheet 経過記録表
B1: 経過記録表 測量期日＿＿＿＿＿ 決済日＿＿＿＿＿ 測量目的 売買・相続・建替・その他（ ）
B2: 土地の所在 | C2: 地番 | D2: 地目 | E2: 地積(㎡) | F2: 所有者名 | G2: 登記簿上の住所 | H2: 電話番号 | I2: 立会予定日 | J2: 立会日 | K2: 訪問履歴 | L2: 備考
A3: 1 | B3: =IF(ISBLANK($A3),0,VLOOKUP($A3,入力シート!$A$7:$J$21,3,FALSE)) -> #REF! | C3: =IF(ISBLANK($A3),0,VLOOKUP($A3,入力シート!$A$7:$J$21,4,FALSE)) -> #REF! | D3: =IF(ISBLANK($A3),0,VLOOKUP($A3,入力シート!$A$7:$J$21,6,FALSE)) -> #REF! | E3: =IF(ISBLANK(A3),0,VLOOKUP(A3,入力シート!$A$7:$J$21,7,FALSE)) -> #REF! | F3: =IF(ISBLANK($A3),0,VLOOKUP($A3,入力シート!$A$7:$J$21,9,FALSE)) -> #REF! | G3: =IF(ISBLANK($A3),0,VLOOKUP($A3,入力シート!$A$7:$J$21,8,FALSE)) -> #REF!
A4: 2 | B4: =IF(ISBLANK($A4),0,IF(A3=A4,0,VLOOKUP($A4,入力シート!$A$7:$J$21,3,FALSE))) -> #REF! | C4: =IF(ISBLANK($A4),0,IF($A3=$A4,0,VLOOKUP($A4,入力シート!$A$7:$J$21,4,FALSE))) -> #REF! | D4: =IF(ISBLANK($A4),0,IF($A3=$A4,0,VLOOKUP($A4,入力シート!$A$7:$J$21,6,FALSE))) -> #REF! | E4: =IF(ISBLANK($A4),0,IF($A3=$A4,0,VLOOKUP($A4,入力シート!$A$7:$J$21,7,FALSE))) -> #REF! | F4: =IF(ISBLANK($A4),0,IF($A3=$A4,VLOOKUP($A4,入力シート!$A$7:$J$21,11,FALSE),VLOOKUP($A4,入力シート!$A$7:$J$21,9,FALSE))) -> #REF! | G4: =IF(ISBLANK($A4),0,IF($A3=$A4,VLOOKUP($A4,入力シート!$A$7:$J$21,10,FALSE),VLOOKUP($A4,入力シート!$A$7:$J$21,8,FALSE))) -> #REF!
A5: 3 | B5: =IF(ISBLANK($A5),0,IF(A4=A5,0,VLOOKUP($A5,入力シート!$A$7:$J$21,3,FALSE))) -> #REF! | C5: =IF(ISBLANK($A5),0,IF($A4=$A5,0,VLOOKUP($A5,入力シート!$A$7:$J$21,4,FALSE))) -> #REF! | D5: =IF(ISBLANK($A5),0,IF($A4=$A5,0,VLOOKUP($A5,入力シート!$A$7:$J$21,6,FALSE))) -> #REF! | E5: =IF(ISBLANK($A5),0,IF($A4=$A5,0,VLOOKUP($A5,入力シート!$A$7:$J$21,7,FALSE))) -> #REF! | F5: =IF(ISBLANK($A5),0,IF($A3=$A5,VLOOKUP($A5,入力シート!$A$7:$J$21,13,FALSE),IF($A4=$A5,VLOOKUP($A5,入力シート!$A$7:$J$21,11,FALSE),VLOOKUP($A5,入力シート!$A$7:$J$21,9,FALSE)))) -> #REF! | G5: =IF(ISBLANK($A5),0,IF($A3=$A5,VLOOKUP($A5,入力シート!$A$7:$J$21,12,FALSE),IF($A4=$A5,VLOOKUP($A5,入力シート!$A$7:$J$21,10,FALSE),VLOOKUP($A5,入力シート!$A$7:$J$21,8,FALSE)))) -> #REF!
A6: 4 | B6: =IF(ISBLANK($A6),0,IF(A5=A6,0,VLOOKUP($A6,入力シート!$A$7:$J$21,3,FALSE))) -> #REF! | C6: =IF(ISBLANK($A6),0,IF($A5=$A6,0,VLOOKUP($A6,入力シート!$A$7:$J$21,4,FALSE))) -> #REF! | D6: =IF(ISBLANK($A6),0,IF($A5=$A6,0,VLOOKUP($A6,入力シート!$A$7:$J$21,6,FALSE))) -> #REF! | E6: =IF(ISBLANK($A6),0,IF($A5=$A6,0,VLOOKUP($A6,入力シート!$A$7:$J$21,7,FALSE))) -> #REF! | F6: =IF(ISBLANK($A6),0,IF($A3=$A6,VLOOKUP($A6,入力シート!$A$7:$J$21,15,FALSE),IF($A4=$A6,VLOOKUP($A6,入力シート!$A$7:$J$21,13,FALSE),IF($A5=$A6,VLOOKUP($A6,入力シート!$A$7:$J$21,11,FALSE),VLOOKUP($A6,入力シート!$A$7:$J$21,9,FALSE))))) -> #REF! | G6: =IF(ISBLANK($A6),0,IF($A3=$A6,VLOOKUP($A6,入力シート!$A$7:$J$21,14,FALSE),IF($A4=$A6,VLOOKUP($A6,入力シート!$A$7:$J$21,12,FALSE),IF($A5=$A6,VLOOKUP($A6,入力シート!$A$7:$J$21,10,FALSE),VLOOKUP($A6,入力シート!$A$7:$J$21,8,FALSE))))) -> #REF!
A7: 5 | B7: =IF(ISBLANK($A7),0,IF(A6=A7,0,VLOOKUP($A7,入力シート!$A$7:$J$21,3,FALSE))) -> #REF! | C7: =IF(ISBLANK($A7),0,IF($A6=$A7,0,VLOOKUP($A7,入力シート!$A$7:$J$21,4,FALSE))) -> #REF! | D7: =IF(ISBLANK($A7),0,IF($A6=$A7,0,VLOOKUP($A7,入力シート!$A$7:$J$21,6,FALSE))) -> #REF! | E7: =IF(ISBLANK($A7),0,IF($A6=$A7,0,VLOOKUP($A7,入力シート!$A$7:$J$21,7,FALSE))) -> #REF! | F7: =IF(ISBLANK($A7),0,IF($A4=$A7,VLOOKUP($A7,入力シート!$A$7:$J$21,15,FALSE),IF($A5=$A7,VLOOKUP($A7,入力シート!$A$7:$J$21,13,FALSE),IF($A6=$A7,VLOOKUP($A7,入力シート!$A$7:$J$21,11,FALSE),VLOOKUP($A7,入力シート!$A$7:$J$21,9,FALSE))))) -> #REF! | G7: =IF(ISBLANK($A7),0,IF($A4=$A7,VLOOKUP($A7,入力シート!$A$7:$J$21,14,FALSE),IF($A5=$A7,VLOOKUP($A7,入力シート!$A$7:$J$21,12,FALSE),IF($A6=$A7,VLOOKUP($A7,入力シート!$A$7:$J$21,10,FALSE),VLOOKUP($A7,入力シート!$A$7:$J$21,8,FALSE))))) -> #REF!
A8: 6 | B8: =IF(ISBLANK($A8),0,IF(A7=A8,0,VLOOKUP($A8,入力シート!$A$7:$J$21,3,FALSE))) -> #REF! | C8: =IF(ISBLANK($A8),0,IF($A7=$A8,0,VLOOKUP($A8,入力シート!$A$7:$J$21,4,FALSE))) -> #REF! | D8: =IF(ISBLANK($A8),0,IF($A7=$A8,0,VLOOKUP($A8,入力シート!$A$7:$J$21,6,FALSE))) -> #REF! | E8: =IF(ISBLANK($A8),0,IF($A7=$A8,0,VLOOKUP($A8,入力シート!$A$7:$J$21,7,FALSE))) -> #REF! | F8: =IF(ISBLANK($A8),0,IF($A5=$A8,VLOOKUP($A8,入力シート!$A$7:$J$21,15,FALSE),IF($A6=$A8,VLOOKUP($A8,入力シート!$A$7:$J$21,13,FALSE),IF($A7=$A8,VLOOKUP($A8,入力シート!$A$7:$J$21,11,FALSE),VLOOKUP($A8,入力シート!$A$7:$J$21,9,FALSE))))) -> #REF! | G8: =IF(ISBLANK($A8),0,IF($A5=$A8,VLOOKUP($A8,入力シート!$A$7:$J$21,14,FALSE),IF($A6=$A8,VLOOKUP($A8,入力シート!$A$7:$J$21,12,FALSE),IF($A7=$A8,VLOOKUP($A8,入力シート!$A$7:$J$21,10,FALSE),VLOOKUP($A8,入力シート!$A$7:$J$21,8,FALSE))))) -> #REF!
A9: 7 | B9: =IF(ISBLANK($A9),0,IF(A8=A9,0,VLOOKUP($A9,入力シート!$A$7:$J$21,3,FALSE))) -> 0 | C9: =IF(ISBLANK($A9),0,IF($A8=$A9,0,VLOOKUP($A9,入力シート!$A$7:$J$21,4,FALSE))) -> 0 | D9: =IF(ISBLANK($A9),0,IF($A8=$A9,0,VLOOKUP($A9,入力シート!$A$7:$J$21,6,FALSE))) -> 0 | E9: =IF(ISBLANK($A9),0,IF($A8=$A9,0,VLOOKUP($A9,入力シート!$A$7:$J$21,7,FALSE))) -> 0 | F9: =IF(ISBLANK($A9),0,IF($A6=$A9,VLOOKUP($A9,入力シート!$A$7:$J$21,15,FALSE),IF($A7=$A9,VLOOKUP($A9,入力シート!$A$7:$J$21,13,FALSE),IF($A8=$A9,VLOOKUP($A9,入力シート!$A$7:$J$21,11,FALSE),VLOOKUP($A9,入力シート!$A$7:$J$21,9,FALSE))))) -> 0 | G9: =IF(ISBLANK($A9),0,IF($A6=$A9,VLOOKUP($A9,入力シート!$A$7:$J$21,14,FALSE),IF($A7=$A9,VLOOKUP($A9,入力シート!$A$7:$J$21,12,FALSE),IF($A8=$A9,VLOOKUP($A9,入力シート!$A$7:$J$21,10,FALSE),VLOOKUP($A9,入力シート!$A$7:$J$21,8,FALSE))))) -> 0
A10: 8 | B10: =IF(ISBLANK($A10),0,IF(A9=A10,0,VLOOKUP($A10,入力シート!$A$7:$J$21,3,FALSE))) -> 0 | C10: =IF(ISBLANK($A10),0,IF($A9=$A10,0,VLOOKUP($A10,入力シート!$A$7:$J$21,4,FALSE))) -> 0 | D10: =IF(ISBLANK($A10),0,IF($A9=$A10,0,VLOOKUP($A10,入力シート!$A$7:$J$21,6,FALSE))) -> 0 | E10: =IF(ISBLANK($A10),0,IF($A9=$A10,0,VLOOKUP($A10,入力シート!$A$7:$J$21,7,FALSE))) -> 0 | F10: =IF(ISBLANK($A10),0,IF($A7=$A10,VLOOKUP($A10,入力シート!$A$7:$J$21,15,FALSE),IF($A8=$A10,VLOOKUP($A10,入力シート!$A$7:$J$21,13,FALSE),IF($A9=$A10,VLOOKUP($A10,入力シート!$A$7:$J$21,11,FALSE),VLOOKUP($A10,入力シート!$A$7:$J$21,9,FALSE))))) -> 0 | G10: =IF(ISBLANK($A10),0,IF($A7=$A10,VLOOKUP($A10,入力シート!$A$7:$J$21,14,FALSE),IF($A8=$A10,VLOOKUP($A10,入力シート!$A$7:$J$21,12,FALSE),IF($A9=$A10,VLOOKUP($A10,入力シート!$A$7:$J$21,10,FALSE),VLOOKUP($A10,入力シート!$A$7:$J$21,8,FALSE))))) -> 0
A11: 9 | B11: =IF(ISBLANK($A11),0,IF(A10=A11,0,VLOOKUP($A11,入力シート!$A$7:$J$21,3,FALSE))) -> 0 | C11: =IF(ISBLANK($A11),0,IF($A10=$A11,0,VLOOKUP($A11,入力シート!$A$7:$J$21,4,FALSE))) -> 0 | D11: =IF(ISBLANK($A11),0,IF($A10=$A11,0,VLOOKUP($A11,入力シート!$A$7:$J$21,6,FALSE))) -> 0 | E11: =IF(ISBLANK($A11),0,IF($A10=$A11,0,VLOOKUP($A11,入力シート!$A$7:$J$21,7,FALSE))) -> 0 | F11: =IF(ISBLANK($A11),0,IF($A8=$A11,VLOOKUP($A11,入力シート!$A$7:$J$21,15,FALSE),IF($A9=$A11,VLOOKUP($A11,入力シート!$A$7:$J$21,13,FALSE),IF($A10=$A11,VLOOKUP($A11,入力シート!$A$7:$J$21,11,FALSE),VLOOKUP($A11,入力シート!$A$7:$J$21,9,FALSE))))) -> 0 | G11: =IF(ISBLANK($A11),0,IF($A8=$A11,VLOOKUP($A11,入力シート!$A$7:$J$21,14,FALSE),IF($A9=$A11,VLOOKUP($A11,入力シート!$A$7:$J$21,12,FALSE),IF($A10=$A11,VLOOKUP($A11,入力シート!$A$7:$J$21,10,FALSE),VLOOKUP($A11,入力シート!$A$7:$J$21,8,FALSE))))) -> 0
A12: 10 | B12: =IF(ISBLANK($A12),0,IF(A11=A12,0,VLOOKUP($A12,入力シート!$A$7:$J$21,3,FALSE))) -> 0 | C12: =IF(ISBLANK($A12),0,IF($A11=$A12,0,VLOOKUP($A12,入力シート!$A$7:$J$21,4,FALSE))) -> 0 | D12: =IF(ISBLANK($A12),0,IF($A11=$A12,0,VLOOKUP($A12,入力シート!$A$7:$J$21,6,FALSE))) -> 0 | E12: =IF(ISBLANK($A12),0,IF($A11=$A12,0,VLOOKUP($A12,入力シート!$A$7:$J$21,7,FALSE))) -> 0 | F12: =IF(ISBLANK($A12),0,IF($A9=$A12,VLOOKUP($A12,入力シート!$A$7:$J$21,15,FALSE),IF($A10=$A12,VLOOKUP($A12,入力シート!$A$7:$J$21,13,FALSE),IF($A11=$A12,VLOOKUP($A12,入力シート!$A$7:$J$21,11,FALSE),VLOOKUP($A12,入力シート!$A$7:$J$21,9,FALSE))))) -> 0 | G12: =IF(ISBLANK($A12),0,IF($A9=$A12,VLOOKUP($A12,入力シート!$A$7:$J$21,14,FALSE),IF($A10=$A12,VLOOKUP($A12,入力シート!$A$7:$J$21,12,FALSE),IF($A11=$A12,VLOOKUP($A12,入力シート!$A$7:$J$21,10,FALSE),VLOOKUP($A12,入力シート!$A$7:$J$21,8,FALSE))))) -> 0
A13: 11 | B13: =IF(ISBLANK($A13),0,IF(A12=A13,0,VLOOKUP($A13,入力シート!$A$7:$J$21,3,FALSE))) -> 0 | C13: =IF(ISBLANK($A13),0,IF($A12=$A13,0,VLOOKUP($A13,入力シート!$A$7:$J$21,4,FALSE))) -> 0 | D13: =IF(ISBLANK($A13),0,IF($A12=$A13,0,VLOOKUP($A13,入力シート!$A$7:$J$21,6,FALSE))) -> 0 | E13: =IF(ISBLANK($A13),0,IF($A12=$A13,0,VLOOKUP($A13,入力シート!$A$7:$J$21,7,FALSE))) -> 0 | F13: =IF(ISBLANK($A13),0,IF($A10=$A13,VLOOKUP($A13,入力シート!$A$7:$J$21,15,FALSE),IF($A11=$A13,VLOOKUP($A13,入力シート!$A$7:$J$21,13,FALSE),IF($A12=$A13,VLOOKUP($A13,入力シート!$A$7:$J$21,11,FALSE),VLOOKUP($A13,入力シート!$A$7:$J$21,9,FALSE))))) -> 0 | G13: =IF(ISBLANK($A13),0,IF($A10=$A13,VLOOKUP($A13,入力シート!$A$7:$J$21,14,FALSE),IF($A11=$A13,VLOOKUP($A13,入力シート!$A$7:$J$21,12,FALSE),IF($A12=$A13,VLOOKUP($A13,入力シート!$A$7:$J$21,10,FALSE),VLOOKUP($A13,入力シート!$A$7:$J$21,8,FALSE))))) -> 0
A14: 12 | B14: =IF(ISBLANK($A14),0,IF(A13=A14,0,VLOOKUP($A14,入力シート!$A$7:$J$21,3,FALSE))) -> 0 | C14: =IF(ISBLANK($A14),0,IF($A13=$A14,0,VLOOKUP($A14,入力シート!$A$7:$J$21,4,FALSE))) -> 0 | D14: =IF(ISBLANK($A14),0,IF($A13=$A14,0,VLOOKUP($A14,入力シート!$A$7:$J$21,6,FALSE))) -> 0 | E14: =IF(ISBLANK($A14),0,IF($A13=$A14,0,VLOOKUP($A14,入力シート!$A$7:$J$21,7,FALSE))) -> 0 | F14: =IF(ISBLANK($A14),0,IF($A11=$A14,VLOOKUP($A14,入力シート!$A$7:$J$21,15,FALSE),IF($A12=$A14,VLOOKUP($A14,入力シート!$A$7:$J$21,13,FALSE),IF($A13=$A14,VLOOKUP($A14,入力シート!$A$7:$J$21,11,FALSE),VLOOKUP($A14,入力シート!$A$7:$J$21,9,FALSE))))) -> 0 | G14: =IF(ISBLANK($A14),0,IF($A11=$A14,VLOOKUP($A14,入力シート!$A$7:$J$21,14,FALSE),IF($A12=$A14,VLOOKUP($A14,入力シート!$A$7:$J$21,12,FALSE),IF($A13=$A14,VLOOKUP($A14,入力シート!$A$7:$J$21,10,FALSE),VLOOKUP($A14,入力シート!$A$7:$J$21,8,FALSE))))) -> 0
A15: 13 | B15: =IF(ISBLANK($A15),0,IF(A14=A15,0,VLOOKUP($A15,入力シート!$A$7:$J$21,3,FALSE))) -> 0 | C15: =IF(ISBLANK($A15),0,IF($A14=$A15,0,VLOOKUP($A15,入力シート!$A$7:$J$21,4,FALSE))) -> 0 | D15: =IF(ISBLANK($A15),0,IF($A14=$A15,0,VLOOKUP($A15,入力シート!$A$7:$J$21,6,FALSE))) -> 0 | E15: =IF(ISBLANK($A15),0,IF($A14=$A15,0,VLOOKUP($A15,入力シート!$A$7:$J$21,7,FALSE))) -> 0 | F15: =IF(ISBLANK($A15),0,IF($A12=$A15,VLOOKUP($A15,入力シート!$A$7:$J$21,15,FALSE),IF($A13=$A15,VLOOKUP($A15,入力シート!$A$7:$J$21,13,FALSE),IF($A14=$A15,VLOOKUP($A15,入力シート!$A$7:$J$21,11,FALSE),VLOOKUP($A15,入力シート!$A$7:$J$21,9,FALSE))))) -> 0 | G15: =IF(ISBLANK($A15),0,IF($A12=$A15,VLOOKUP($A15,入力シート!$A$7:$J$21,14,FALSE),IF($A13=$A15,VLOOKUP($A15,入力シート!$A$7:$J$21,12,FALSE),IF($A14=$A15,VLOOKUP($A15,入力シート!$A$7:$J$21,10,FALSE),VLOOKUP($A15,入力シート!$A$7:$J$21,8,FALSE))))) -> 0

Sheet 土地登記簿調書
C1: 土地登記簿調書
B2: 所在 | C2: =入力シート!C7 -> #REF! | G2: 令和１８年７月１３日現在 東京法務局港出張所
B3: 地番 | C3: 地目 | D3: 地積(㎡) | E3: 所有者住所 | F3: 所有者名 | G3: 摘要
A4: 1 | B4: =IF(ISBLANK($A4),0,VLOOKUP($A4,入力シート!$A$7:$J$21,4,FALSE)) -> #REF! | C4: =IF(ISBLANK($A4),0,VLOOKUP($A4,入力シート!$A$7:$J$21,6,FALSE)) -> #REF! | D4: =IF(ISBLANK(A4),0,VLOOKUP(A4,入力シート!$A$7:$J$21,7,FALSE)) -> #REF! | E4: =IF(ISBLANK($A4),0,VLOOKUP($A4,入力シート!$A$7:$J$21,8,FALSE)) -> #REF! | F4: =IF(ISBLANK($A4),0,VLOOKUP($A4,入力シート!$A$7:$J$21,9,FALSE)) -> #REF!
A5: 2 | B5: =IF(ISBLANK($A5),0,VLOOKUP($A5,入力シート!$A$7:$J$21,4,FALSE)) -> #REF! | C5: =IF(ISBLANK($A5),0,VLOOKUP($A5,入力シート!$A$7:$J$21,6,FALSE)) -> #REF! | D5: =IF(ISBLANK(A5),0,VLOOKUP(A5,入力シート!$A$7:$J$21,7,FALSE)) -> #REF! | E5: =IF(ISBLANK($A5),0,VLOOKUP($A5,入力シート!$A$7:$J$21,8,FALSE)) -> #REF! | F5: =IF(ISBLANK($A5),0,VLOOKUP($A5,入力シート!$A$7:$J$21,9,FALSE)) -> #REF!
A6: 3 | B6: =IF(ISBLANK($A6),0,VLOOKUP($A6,入力シート!$A$7:$J$21,4,FALSE)) -> #REF! | C6: =IF(ISBLANK($A6),0,VLOOKUP($A6,入力シート!$A$7:$J$21,6,FALSE)) -> #REF! | D6: =IF(ISBLANK(A6),0,VLOOKUP(A6,入力シート!$A$7:$J$21,7,FALSE)) -> #REF! | E6: =IF(ISBLANK($A6),0,VLOOKUP($A6,入力シート!$A$7:$J$21,8,FALSE)) -> #REF! | F6: =IF(ISBLANK($A6),0,VLOOKUP($A6,入力シート!$A$7:$J$21,9,FALSE)) -> #REF!
A7: 4 | B7: =IF(ISBLANK($A7),0,VLOOKUP($A7,入力シート!$A$7:$J$21,4,FALSE)) -> #REF! | C7: =IF(ISBLANK($A7),0,VLOOKUP($A7,入力シート!$A$7:$J$21,6,FALSE)) -> #REF! | D7: =IF(ISBLANK(A7),0,VLOOKUP(A7,入力シート!$A$7:$J$21,7,FALSE)) -> #REF! | E7: =IF(ISBLANK($A7),0,VLOOKUP($A7,入力シート!$A$7:$J$21,8,FALSE)) -> #REF! | F7: =IF(ISBLANK($A7),0,VLOOKUP($A7,入力シート!$A$7:$J$21,9,FALSE)) -> #REF!
A8: 5 | B8: =IF(ISBLANK($A8),0,VLOOKUP($A8,入力シート!$A$7:$J$21,4,FALSE)) -> #REF! | C8: =IF(ISBLANK($A8),0,VLOOKUP($A8,入力シート!$A$7:$J$21,6,FALSE)) -> #REF! | D8: =IF(ISBLANK(A8),0,VLOOKUP(A8,入力シート!$A$7:$J$21,7,FALSE)) -> #REF! | E8: =IF(ISBLANK($A8),0,VLOOKUP($A8,入力シート!$A$7:$J$21,8,FALSE)) -> #REF! | F8: =IF(ISBLANK($A8),0,VLOOKUP($A8,入力シート!$A$7:$J$21,9,FALSE)) -> #REF!
A9: 6 | B9: =IF(ISBLANK($A9),0,VLOOKUP($A9,入力シート!$A$7:$J$21,4,FALSE)) -> #REF! | C9: =IF(ISBLANK($A9),0,VLOOKUP($A9,入力シート!$A$7:$J$21,6,FALSE)) -> #REF! | D9: =IF(ISBLANK(A9),0,VLOOKUP(A9,入力シート!$A$7:$J$21,7,FALSE)) -> #REF! | E9: =IF(ISBLANK($A9),0,VLOOKUP($A9,入力シート!$A$7:$J$21,8,FALSE)) -> #REF! | F9: =IF(ISBLANK($A9),0,VLOOKUP($A9,入力シート!$A$7:$J$21,9,FALSE)) -> #REF!
A10: 7 | B10: =IF(ISBLANK($A10),0,VLOOKUP($A10,入力シート!$A$7:$J$21,4,FALSE)) -> 0 | C10: =IF(ISBLANK($A10),0,VLOOKUP($A10,入力シート!$A$7:$J$21,6,FALSE)) -> 0 | D10: =IF(ISBLANK(A10),0,VLOOKUP(A10,入力シート!$A$7:$J$21,7,FALSE)) -> 0 | E10: =IF(ISBLANK($A10),0,VLOOKUP($A10,入力シート!$A$7:$J$21,8,FALSE)) -> 0 | F10: =IF(ISBLANK($A10),0,VLOOKUP($A10,入力シート!$A$7:$J$21,9,FALSE)) -> 0
A11: 8 | B11: =IF(ISBLANK($A11),0,VLOOKUP($A11,入力シート!$A$7:$J$21,4,FALSE)) -> 0 | C11: =IF(ISBLANK($A11),0,VLOOKUP($A11,入力シート!$A$7:$J$21,6,FALSE)) -> 0 | D11: =IF(ISBLANK(A11),0,VLOOKUP(A11,入力シート!$A$7:$J$21,7,FALSE)) -> 0 | E11: =IF(ISBLANK($A11),0,VLOOKUP($A11,入力シート!$A$7:$J$21,8,FALSE)) -> 0 | F11: =IF(ISBLANK($A11),0,VLOOKUP($A11,入力シート!$A$7:$J$21,9,FALSE)) -> 0
A12: 9 | B12: =IF(ISBLANK($A12),0,VLOOKUP($A12,入力シート!$A$7:$J$21,4,FALSE)) -> 0 | C12: =IF(ISBLANK($A12),0,VLOOKUP($A12,入力シート!$A$7:$J$21,6,FALSE)) -> 0 | D12: =IF(ISBLANK(A12),0,VLOOKUP(A12,入力シート!$A$7:$J$21,7,FALSE)) -> 0 | E12: =IF(ISBLANK($A12),0,VLOOKUP($A12,入力シート!$A$7:$J$21,8,FALSE)) -> 0 | F12: =IF(ISBLANK($A12),0,VLOOKUP($A12,入力シート!$A$7:$J$21,9,FALSE)) -> 0
A13: 10 | B13: =IF(ISBLANK($A13),0,VLOOKUP($A13,入力シート!$A$7:$J$21,4,FALSE)) -> 0 | C13: =IF(ISBLANK($A13),0,VLOOKUP($A13,入力シート!$A$7:$J$21,6,FALSE)) -> 0 | D13: =IF(ISBLANK(A13),0,VLOOKUP(A13,入力シート!$A$7:$J$21,7,FALSE)) -> 0 | E13: =IF(ISBLANK($A13),0,VLOOKUP($A13,入力シート!$A$7:$J$21,8,FALSE)) -> 0 | F13: =IF(ISBLANK($A13),0,VLOOKUP($A13,入力シート!$A$7:$J$21,9,FALSE)) -> 0
A14: 11 | B14: =IF(ISBLANK($A14),0,VLOOKUP($A14,入力シート!$A$7:$J$21,4,FALSE)) -> 0 | C14: =IF(ISBLANK($A14),0,VLOOKUP($A14,入力シート!$A$7:$J$21,6,FALSE)) -> 0 | D14: =IF(ISBLANK(A14),0,VLOOKUP(A14,入力シート!$A$7:$J$21,7,FALSE)) -> 0 | E14: =IF(ISBLANK($A14),0,VLOOKUP($A14,入力シート!$A$7:$J$21,8,FALSE)) -> 0 | F14: =IF(ISBLANK($A14),0,VLOOKUP($A14,入力シート!$A$7:$J$21,9,FALSE)) -> 0

Sheet 土地所有者一覧表
C1: 土地所有者一覧表
B2: 所在 | C2: =入力シート!C7 -> #REF! | G2: 令和１８年７月１３日現在 東京法務局港出張所
B3: 地番 | C3: 地目 | D3: 地積(㎡) | E3: 所有者住所 | F3: 所有者名 | G3: 摘要
A4: 1 | B4: =IF(ISBLANK($A4),0,VLOOKUP($A4,入力シート!$A$7:$J$21,4,FALSE)) -> #REF! | C4: =IF(ISBLANK($A4),0,VLOOKUP($A4,入力シート!$A$7:$J$21,6,FALSE)) -> #REF! | D4: =IF(ISBLANK(A4),0,VLOOKUP(A4,入力シート!$A$7:$J$21,7,FALSE)) -> #REF! | E4: =IF(ISBLANK($A4),0,VLOOKUP($A4,入力シート!$A$7:$J$21,8,FALSE)) -> #REF! | F4: =IF(ISBLANK($A4),0,VLOOKUP($A4,入力シート!$A$7:$J$21,9,FALSE)) -> #REF!
A5: 2 | B5: =IF(ISBLANK($A5),0,VLOOKUP($A5,入力シート!$A$7:$J$21,4,FALSE)) -> #REF! | C5: =IF(ISBLANK($A5),0,VLOOKUP($A5,入力シート!$A$7:$J$21,6,FALSE)) -> #REF! | D5: =IF(ISBLANK(A5),0,VLOOKUP(A5,入力シート!$A$7:$J$21,7,FALSE)) -> #REF! | E5: =IF(ISBLANK($A5),0,VLOOKUP($A5,入力シート!$A$7:$J$21,8,FALSE)) -> #REF! | F5: =IF(ISBLANK($A5),0,VLOOKUP($A5,入力シート!$A$7:$J$21,9,FALSE)) -> #REF!
A6: 3 | B6: =IF(ISBLANK($A6),0,VLOOKUP($A6,入力シート!$A$7:$J$21,4,FALSE)) -> #REF! | C6: =IF(ISBLANK($A6),0,VLOOKUP($A6,入力シート!$A$7:$J$21,6,FALSE)) -> #REF! | D6: =IF(ISBLANK(A6),0,VLOOKUP(A6,入力シート!$A$7:$J$21,7,FALSE)) -> #REF! | E6: =IF(ISBLANK($A6),0,VLOOKUP($A6,入力シート!$A$7:$J$21,8,FALSE)) -> #REF! | F6: =IF(ISBLANK($A6),0,VLOOKUP($A6,入力シート!$A$7:$J$21,9,FALSE)) -> #REF!
A7: 4 | B7: =IF(ISBLANK($A7),0,VLOOKUP($A7,入力シート!$A$7:$J$21,4,FALSE)) -> #REF! | C7: =IF(ISBLANK($A7),0,VLOOKUP($A7,入力シート!$A$7:$J$21,6,FALSE)) -> #REF! | D7: =IF(ISBLANK(A7),0,VLOOKUP(A7,入力シート!$A$7:$J$21,7,FALSE)) -> #REF! | E7: =IF(ISBLANK($A7),0,VLOOKUP($A7,入力シート!$A$7:$J$21,8,FALSE)) -> #REF! | F7: =IF(ISBLANK($A7),0,VLOOKUP($A7,入力シート!$A$7:$J$21,9,FALSE)) -> #REF!
A8: 5 | B8: =IF(ISBLANK($A8),0,VLOOKUP($A8,入力シート!$A$7:$J$21,4,FALSE)) -> #REF! | C8: =IF(ISBLANK($A8),0,VLOOKUP($A8,入力シート!$A$7:$J$21,6,FALSE)) -> #REF! | D8: =IF(ISBLANK(A8),0,VLOOKUP(A8,入力シート!$A$7:$J$21,7,FALSE)) -> #REF! | E8: =IF(ISBLANK($A8),0,VLOOKUP($A8,入力シート!$A$7:$J$21,8,FALSE)) -> #REF! | F8: =IF(ISBLANK($A8),0,VLOOKUP($A8,入力シート!$A$7:$J$21,9,FALSE)) -> #REF!
A9: 6 | B9: =IF(ISBLANK($A9),0,VLOOKUP($A9,入力シート!$A$7:$J$21,4,FALSE)) -> #REF! | C9: =IF(ISBLANK($A9),0,VLOOKUP($A9,入力シート!$A$7:$J$21,6,FALSE)) -> #REF! | D9: =IF(ISBLANK(A9),0,VLOOKUP(A9,入力シート!$A$7:$J$21,7,FALSE)) -> #REF! | E9: =IF(ISBLANK($A9),0,VLOOKUP($A9,入力シート!$A$7:$J$21,8,FALSE)) -> #REF! | F9: =IF(ISBLANK($A9),0,VLOOKUP($A9,入力シート!$A$7:$J$21,9,FALSE)) -> #REF!
A10: 7 | B10: =IF(ISBLANK($A10),0,VLOOKUP($A10,入力シート!$A$7:$J$21,4,FALSE)) -> 0 | C10: =IF(ISBLANK($A10),0,VLOOKUP($A10,入力シート!$A$7:$J$21,6,FALSE)) -> 0 | D10: =IF(ISBLANK(A10),0,VLOOKUP(A10,入力シート!$A$7:$J$21,7,FALSE)) -> 0 | E10: =IF(ISBLANK($A10),0,VLOOKUP($A10,入力シート!$A$7:$J$21,8,FALSE)) -> 0 | F10: =IF(ISBLANK($A10),0,VLOOKUP($A10,入力シート!$A$7:$J$21,9,FALSE)) -> 0
A11: 8 | B11: =IF(ISBLANK($A11),0,VLOOKUP($A11,入力シート!$A$7:$J$21,4,FALSE)) -> 0 | C11: =IF(ISBLANK($A11),0,VLOOKUP($A11,入力シート!$A$7:$J$21,6,FALSE)) -> 0 | D11: =IF(ISBLANK(A11),0,VLOOKUP(A11,入力シート!$A$7:$J$21,7,FALSE)) -> 0 | E11: =IF(ISBLANK($A11),0,VLOOKUP($A11,入力シート!$A$7:$J$21,8,FALSE)) -> 0 | F11: =IF(ISBLANK($A11),0,VLOOKUP($A11,入力シート!$A$7:$J$21,9,FALSE)) -> 0
A12: 9 | B12: =IF(ISBLANK($A12),0,VLOOKUP($A12,入力シート!$A$7:$J$21,4,FALSE)) -> 0 | C12: =IF(ISBLANK($A12),0,VLOOKUP($A12,入力シート!$A$7:$J$21,6,FALSE)) -> 0 | D12: =IF(ISBLANK(A12),0,VLOOKUP(A12,入力シート!$A$7:$J$21,7,FALSE)) -> 0 | E12: =IF(ISBLANK($A12),0,VLOOKUP($A12,入力シート!$A$7:$J$21,8,FALSE)) -> 0 | F12: =IF(ISBLANK($A12),0,VLOOKUP($A12,入力シート!$A$7:$J$21,9,FALSE)) -> 0
A13: 10 | B13: =IF(ISBLANK($A13),0,VLOOKUP($A13,入力シート!$A$7:$J$21,4,FALSE)) -> 0 | C13: =IF(ISBLANK($A13),0,VLOOKUP($A13,入力シート!$A$7:$J$21,6,FALSE)) -> 0 | D13: =IF(ISBLANK(A13),0,VLOOKUP(A13,入力シート!$A$7:$J$21,7,FALSE)) -> 0 | E13: =IF(ISBLANK($A13),0,VLOOKUP($A13,入力シート!$A$7:$J$21,8,FALSE)) -> 0 | F13: =IF(ISBLANK($A13),0,VLOOKUP($A13,入力シート!$A$7:$J$21,9,FALSE)) -> 0
A14: 11 | B14: =IF(ISBLANK($A14),0,VLOOKUP($A14,入力シート!$A$7:$J$21,4,FALSE)) -> 0 | C14: =IF(ISBLANK($A14),0,VLOOKUP($A14,入力シート!$A$7:$J$21,6,FALSE)) -> 0 | D14: =IF(ISBLANK(A14),0,VLOOKUP(A14,入力シート!$A$7:$J$21,7,FALSE)) -> 0 | E14: =IF(ISBLANK($A14),0,VLOOKUP($A14,入力シート!$A$7:$J$21,8,FALSE)) -> 0 | F14: =IF(ISBLANK($A14),0,VLOOKUP($A14,入力シート!$A$7:$J$21,9,FALSE)) -> 0

Sheet 所有者調書(大田)
B1: 土 地 所 有 者 調 書
B3: 土地所在 | C3: 地番 | D3: 地目 | E3: 地積 | F3: 登記 年月日 | G3: 所有者名 | H3: 土地登記記録上の住所
H4: 住民登録してある住所
A5: 1 | B5: =IF(ISBLANK($A5), "", VLOOKUP($A5, 入力シート!$A$7:$J$1000, 3, FALSE)) -> #REF! | C5: =IF(ISBLANK($A5), "", VLOOKUP($A5, 入力シート!$A$7:$J$1000, 4, FALSE)) -> #REF! | D5: =IF(ISBLANK($A5), "", VLOOKUP($A5, 入力シート!$A$7:$J$1000, 6, FALSE)) -> #REF! | E5: =IF(ISBLANK($A5), "", VLOOKUP($A5, 入力シート!$A$7:$J$1000, 7, FALSE)) -> #REF! | F5: =IF(ISBLANK($A5), "", VLOOKUP($A5, 入力シート!$A$7:$J$1000, 10, FALSE)) -> #REF! | G5: =IF(ISBLANK($A5), "", VLOOKUP($A5, 入力シート!$A$7:$J$1000, 9, FALSE)) -> #REF! | H5: =IF(ISBLANK($A5), "", VLOOKUP($A5, 入力シート!$A$7:$J$1000, 8, FALSE)) -> #REF!
A7: 2 | B7: =IF(ISBLANK($A7), "", VLOOKUP($A7, 入力シート!$A$7:$J$1000, 3, FALSE)) -> #REF! | C7: =IF(ISBLANK($A7), "", VLOOKUP($A7, 入力シート!$A$7:$J$1000, 4, FALSE)) -> #REF! | D7: =IF(ISBLANK($A7), "", VLOOKUP($A7, 入力シート!$A$7:$J$1000, 6, FALSE)) -> #REF! | E7: =IF(ISBLANK($A7), "", VLOOKUP($A7, 入力シート!$A$7:$J$1000, 7, FALSE)) -> #REF! | F7: =IF(ISBLANK($A7), "", VLOOKUP($A7, 入力シート!$A$7:$J$1000, 10, FALSE)) -> #REF! | G7: =IF(ISBLANK($A7), "", VLOOKUP($A7, 入力シート!$A$7:$J$1000, 9, FALSE)) -> #REF! | H7: =IF(ISBLANK($A7), "", VLOOKUP($A7, 入力シート!$A$7:$J$1000, 8, FALSE)) -> #REF!
A9: 3 | B9: =IF(ISBLANK($A9), "", VLOOKUP($A9, 入力シート!$A$7:$J$1000, 3, FALSE)) -> #REF! | C9: =IF(ISBLANK($A9), "", VLOOKUP($A9, 入力シート!$A$7:$J$1000, 4, FALSE)) -> #REF! | D9: =IF(ISBLANK($A9), "", VLOOKUP($A9, 入力シート!$A$7:$J$1000, 6, FALSE)) -> #REF! | E9: =IF(ISBLANK($A9), "", VLOOKUP($A9, 入力シート!$A$7:$J$1000, 7, FALSE)) -> #REF! | F9: =IF(ISBLANK($A9), "", VLOOKUP($A9, 入力シート!$A$7:$J$1000, 10, FALSE)) -> #REF! | G9: =IF(ISBLANK($A9), "", VLOOKUP($A9, 入力シート!$A$7:$J$1000, 9, FALSE)) -> #REF! | H9: =IF(ISBLANK($A9), "", VLOOKUP($A9, 入力シート!$A$7:$J$1000, 8, FALSE)) -> #REF!
A11: 4 | B11: =IF(ISBLANK($A11), "", VLOOKUP($A11, 入力シート!$A$7:$J$1000, 3, FALSE)) -> #REF! | C11: =IF(ISBLANK($A11), "", VLOOKUP($A11, 入力シート!$A$7:$J$1000, 4, FALSE)) -> #REF! | D11: =IF(ISBLANK($A11), "", VLOOKUP($A11, 入力シート!$A$7:$J$1000, 6, FALSE)) -> #REF! | E11: =IF(ISBLANK($A11), "", VLOOKUP($A11, 入力シート!$A$7:$J$1000, 7, FALSE)) -> #REF! | F11: =IF(ISBLANK($A11), "", VLOOKUP($A11, 入力シート!$A$7:$J$1000, 10, FALSE)) -> #REF! | G11: =IF(ISBLANK($A11), "", VLOOKUP($A11, 入力シート!$A$7:$J$1000, 9, FALSE)) -> #REF! | H11: =IF(ISBLANK($A11), "", VLOOKUP($A11, 入力シート!$A$7:$J$1000, 8, FALSE)) -> #REF!
A13: 5 | B13: =IF(ISBLANK($A13), "", VLOOKUP($A13, 入力シート!$A$7:$J$1000, 3, FALSE)) -> #REF! | C13: =IF(ISBLANK($A13), "", VLOOKUP($A13, 入力シート!$A$7:$J$1000, 4, FALSE)) -> #REF! | D13: =IF(ISBLANK($A13), "", VLOOKUP($A13, 入力シート!$A$7:$J$1000, 6, FALSE)) -> #REF! | E13: =IF(ISBLANK($A13), "", VLOOKUP($A13, 入力シート!$A$7:$J$1000, 7, FALSE)) -> #REF! | F13: =IF(ISBLANK($A13), "", VLOOKUP($A13, 入力シート!$A$7:$J$1000, 10, FALSE)) -> #REF! | G13: =IF(ISBLANK($A13), "", VLOOKUP($A13, 入力シート!$A$7:$J$1000, 9, FALSE)) -> #REF! | H13: =IF(ISBLANK($A13), "", VLOOKUP($A13, 入力シート!$A$7:$J$1000, 8, FALSE)) -> #REF!
A15: 6 | B15: =IF(ISBLANK($A15), "", VLOOKUP($A15, 入力シート!$A$7:$J$1000, 3, FALSE)) -> #REF! | C15: =IF(ISBLANK($A15), "", VLOOKUP($A15, 入力シート!$A$7:$J$1000, 4, FALSE)) -> #REF! | D15: =IF(ISBLANK($A15), "", VLOOKUP($A15, 入力シート!$A$7:$J$1000, 6, FALSE)) -> #REF! | E15: =IF(ISBLANK($A15), "", VLOOKUP($A15, 入力シート!$A$7:$J$1000, 7, FALSE)) -> #REF! | F15: =IF(ISBLANK($A15), "", VLOOKUP($A15, 入力シート!$A$7:$J$1000, 10, FALSE)) -> #REF! | G15: =IF(ISBLANK($A15), "", VLOOKUP($A15, 入力シート!$A$7:$J$1000, 9, FALSE)) -> #REF! | H15: =IF(ISBLANK($A15), "", VLOOKUP($A15, 入力シート!$A$7:$J$1000, 8, FALSE)) -> #REF!
A17: 7 | B17: =IF(ISBLANK($A17), "", VLOOKUP($A17, 入力シート!$A$7:$J$1000, 3, FALSE)) -> 0 | C17: =IF(ISBLANK($A17), "", VLOOKUP($A17, 入力シート!$A$7:$J$1000, 4, FALSE)) -> 0 | D17: =IF(ISBLANK($A17), "", VLOOKUP($A17, 入力シート!$A$7:$J$1000, 6, FALSE)) -> 0 | E17: =IF(ISBLANK($A17), "", VLOOKUP($A17, 入力シート!$A$7:$J$1000, 7, FALSE)) -> 0 | F17: =IF(ISBLANK($A17), "", VLOOKUP($A17, 入力シート!$A$7:$J$1000, 10, FALSE)) -> 0 | G17: =IF(ISBLANK($A17), "", VLOOKUP($A17, 入力シート!$A$7:$J$1000, 9, FALSE)) -> 0 | H17: =IF(ISBLANK($A17), "", VLOOKUP($A17, 入力シート!$A$7:$J$1000, 8, FALSE)) -> 0
A19: 8 | B19: =IF(ISBLANK($A19), "", VLOOKUP($A19, 入力シート!$A$7:$J$1000, 3, FALSE)) -> 0 | C19: =IF(ISBLANK($A19), "", VLOOKUP($A19, 入力シート!$A$7:$J$1000, 4, FALSE)) -> 0 | D19: =IF(ISBLANK($A19), "", VLOOKUP($A19, 入力シート!$A$7:$J$1000, 6, FALSE)) -> 0 | E19: =IF(ISBLANK($A19), "", VLOOKUP($A19, 入力シート!$A$7:$J$1000, 7, FALSE)) -> 0 | F19: =IF(ISBLANK($A19), "", VLOOKUP($A19, 入力シート!$A$7:$J$1000, 10, FALSE)) -> 0 | G19: =IF(ISBLANK($A19), "", VLOOKUP($A19, 入力シート!$A$7:$J$1000, 9, FALSE)) -> 0 | H19: =IF(ISBLANK($A19), "", VLOOKUP($A19, 入力シート!$A$7:$J$1000, 8, FALSE)) -> 0
A21: 9 | B21: =IF(ISBLANK($A21), "", VLOOKUP($A21, 入力シート!$A$7:$J$1000, 3, FALSE)) -> 0 | C21: =IF(ISBLANK($A21), "", VLOOKUP($A21, 入力シート!$A$7:$J$1000, 4, FALSE)) -> 0 | D21: =IF(ISBLANK($A21), "", VLOOKUP($A21, 入力シート!$A$7:$J$1000, 6, FALSE)) -> 0 | E21: =IF(ISBLANK($A21), "", VLOOKUP($A21, 入力シート!$A$7:$J$1000, 7, FALSE)) -> 0 | F21: =IF(ISBLANK($A21), "", VLOOKUP($A21, 入力シート!$A$7:$J$1000, 10, FALSE)) -> 0 | G21: =IF(ISBLANK($A21), "", VLOOKUP($A21, 入力シート!$A$7:$J$1000, 9, FALSE)) -> 0 | H21: =IF(ISBLANK($A21), "", VLOOKUP($A21, 入力シート!$A$7:$J$1000, 8, FALSE)) -> 0
A23: 10 | B23: =IF(ISBLANK($A23), "", VLOOKUP($A23, 入力シート!$A$7:$J$1000, 3, FALSE)) -> 0 | C23: =IF(ISBLANK($A23), "", VLOOKUP($A23, 入力シート!$A$7:$J$1000, 4, FALSE)) -> 0 | D23: =IF(ISBLANK($A23), "", VLOOKUP($A23, 入力シート!$A$7:$J$1000, 6, FALSE)) -> 0 | E23: =IF(ISBLANK($A23), "", VLOOKUP($A23, 入力シート!$A$7:$J$1000, 7, FALSE)) -> 0 | F23: =IF(ISBLANK($A23), "", VLOOKUP($A23, 入力シート!$A$7:$J$1000, 10, FALSE)) -> 0 | G23: =IF(ISBLANK($A23), "", VLOOKUP($A23, 入力シート!$A$7:$J$1000, 9, FALSE)) -> 0 | H23: =IF(ISBLANK($A23), "", VLOOKUP($A23, 入力シート!$A$7:$J$1000, 8, FALSE)) -> 0
A25: 11 | B25: =IF(ISBLANK($A25), "", VLOOKUP($A25, 入力シート!$A$7:$J$1000, 3, FALSE)) -> 0 | C25: =IF(ISBLANK($A25), "", VLOOKUP($A25, 入力シート!$A$7:$J$1000, 4, FALSE)) -> 0 | D25: =IF(ISBLANK($A25), "", VLOOKUP($A25, 入力シート!$A$7:$J$1000, 6, FALSE)) -> 0 | E25: =IF(ISBLANK($A25), "", VLOOKUP($A25, 入力シート!$A$7:$J$1000, 7, FALSE)) -> 0 | F25: =IF(ISBLANK($A25), "", VLOOKUP($A25, 入力シート!$A$7:$J$1000, 10, FALSE)) -> 0 | G25: =IF(ISBLANK($A25), "", VLOOKUP($A25, 入力シート!$A$7:$J$1000, 9, FALSE)) -> 0 | H25: =IF(ISBLANK($A25), "", VLOOKUP($A25, 入力シート!$A$7:$J$1000, 8, FALSE)) -> 0
A27: 12 | B27: =IF(ISBLANK($A27), "", VLOOKUP($A27, 入力シート!$A$7:$J$1000, 3, FALSE)) -> 0 | C27: =IF(ISBLANK($A27), "", VLOOKUP($A27, 入力シート!$A$7:$J$1000, 4, FALSE)) -> 0 | D27: =IF(ISBLANK($A27), "", VLOOKUP($A27, 入力シート!$A$7:$J$1000, 6, FALSE)) -> 0 | E27: =IF(ISBLANK($A27), "", VLOOKUP($A27, 入力シート!$A$7:$J$1000, 7, FALSE)) -> 0 | F27: =IF(ISBLANK($A27), "", VLOOKUP($A27, 入力シート!$A$7:$J$1000, 10, FALSE)) -> 0 | G27: =IF(ISBLANK($A27), "", VLOOKUP($A27, 入力シート!$A$7:$J$1000, 9, FALSE)) -> 0 | H27: =IF(ISBLANK($A27), "", VLOOKUP($A27, 入力シート!$A$7:$J$1000, 8, FALSE)) -> 0
... A31: 14 | B31: =IF(ISBLANK($A31), "", VLOOKUP($A31, 入力シート!$A$7:$J$1000, 3, FALSE)) -> 0 | C31: =IF(ISBLANK($A31), "", VLOOKUP($A31, 入力シート!$A$7:$J$1000, 4, FALSE)) -> 0 | D31: =IF(ISBLANK($A31), "", VLOOKUP($A31, 入力シート!$A$7:$J$1000, 6, FALSE)) -> 0 | E31: =IF(ISBLANK($A31), "", VLOOKUP($A31, 入力シート!$A$7:$J$1000, 7, FALSE)) -> 0 | F31: =IF(ISBLANK($A31), "", VLOOKUP($A31, 入力シート!$A$7:$J$1000, 10, FALSE)) -> 0 | G31: =IF(ISBLANK($A31), "", VLOOKUP($A31, 入力シート!$A$7:$J$1000, 9, FALSE)) -> 0 | H31: =IF(ISBLANK($A31), "", VLOOKUP($A31, 入力シート!$A$7:$J$1000, 8, FALSE)) -> 0

Sheet 所有者調書(板橋)
B1: 土 地 所 有 者 調 書
C2: =TODAY() -> 45779 | F2: 調査・作成者氏名 岡藤央樹 印
B3: 土地所在 | C3: 地番 | D3: 地目 | E3: 地積 | F3: 登記 年月日 | G3: 所有者名 | H3: 土地登記簿の住所
H4: 住民登録してある住所
A5: 1 | B5: =IF(ISBLANK($A5), "", VLOOKUP($A5, 入力シート!$A$7:$J$1000, 3, FALSE)) -> #REF! | C5: =IF(ISBLANK($A5), "", VLOOKUP($A5, 入力シート!$A$7:$J$1000, 4, FALSE)) -> #REF! | D5: =IF(ISBLANK($A5), "", VLOOKUP($A5, 入力シート!$A$7:$J$1000, 6, FALSE)) -> #REF! | E5: =IF(ISBLANK($A5), "", VLOOKUP($A5, 入力シート!$A$7:$J$1000, 7, FALSE)) -> #REF! | F5: =IF(ISBLANK($A5), "", VLOOKUP($A5, 入力シート!$A$7:$J$1000, 10, FALSE)) -> #REF! | G5: =IF(ISBLANK($A5), "", VLOOKUP($A5, 入力シート!$A$7:$J$1000, 9, FALSE)) -> #REF! | H5: =IF(ISBLANK($A5), "", VLOOKUP($A5, 入力シート!$A$7:$J$1000, 8, FALSE)) -> #REF!
A7: 2 | B7: =IF(ISBLANK($A7), "", VLOOKUP($A7, 入力シート!$A$7:$J$1000, 3, FALSE)) -> #REF! | C7: =IF(ISBLANK($A7), "", VLOOKUP($A7, 入力シート!$A$7:$J$1000, 4, FALSE)) -> #REF! | D7: =IF(ISBLANK($A7), "", VLOOKUP($A7, 入力シート!$A$7:$J$1000, 6, FALSE)) -> #REF! | E7: =IF(ISBLANK($A7), "", VLOOKUP($A7, 入力シート!$A$7:$J$1000, 7, FALSE)) -> #REF! | F7: =IF(ISBLANK($A7), "", VLOOKUP($A7, 入力シート!$A$7:$J$1000, 10, FALSE)) -> #REF! | G7: =IF(ISBLANK($A7), "", VLOOKUP($A7, 入力シート!$A$7:$J$1000, 9, FALSE)) -> #REF! | H7: =IF(ISBLANK($A7), "", VLOOKUP($A7, 入力シート!$A$7:$J$1000, 8, FALSE)) -> #REF!
A9: 3 | B9: =IF(ISBLANK($A9), "", VLOOKUP($A9, 入力シート!$A$7:$J$1000, 3, FALSE)) -> #REF! | C9: =IF(ISBLANK($A9), "", VLOOKUP($A9, 入力シート!$A$7:$J$1000, 4, FALSE)) -> #REF! | D9: =IF(ISBLANK($A9), "", VLOOKUP($A9, 入力シート!$A$7:$J$1000, 6, FALSE)) -> #REF! | E9: =IF(ISBLANK($A9), "", VLOOKUP($A9, 入力シート!$A$7:$J$1000, 7, FALSE)) -> #REF! | F9: =IF(ISBLANK($A9), "", VLOOKUP($A9, 入力シート!$A$7:$J$1000, 10, FALSE)) -> #REF! | G9: =IF(ISBLANK($A9), "", VLOOKUP($A9, 入力シート!$A$7:$J$1000, 9, FALSE)) -> #REF! | H9: =IF(ISBLANK($A9), "", VLOOKUP($A9, 入力シート!$A$7:$J$1000, 8, FALSE)) -> #REF!
A11: 4 | B11: =IF(ISBLANK($A11), "", VLOOKUP($A11, 入力シート!$A$7:$J$1000, 3, FALSE)) -> #REF! | C11: =IF(ISBLANK($A11), "", VLOOKUP($A11, 入力シート!$A$7:$J$1000, 4, FALSE)) -> #REF! | D11: =IF(ISBLANK($A11), "", VLOOKUP($A11, 入力シート!$A$7:$J$1000, 6, FALSE)) -> #REF! | E11: =IF(ISBLANK($A11), "", VLOOKUP($A11, 入力シート!$A$7:$J$1000, 7, FALSE)) -> #REF! | F11: =IF(ISBLANK($A11), "", VLOOKUP($A11, 入力シート!$A$7:$J$1000, 10, FALSE)) -> #REF! | G11: =IF(ISBLANK($A11), "", VLOOKUP($A11, 入力シート!$A$7:$J$1000, 9, FALSE)) -> #REF! | H11: =IF(ISBLANK($A11), "", VLOOKUP($A11, 入力シート!$A$7:$J$1000, 8, FALSE)) -> #REF!
A13: 5 | B13: =IF(ISBLANK($A13), "", VLOOKUP($A13, 入力シート!$A$7:$J$1000, 3, FALSE)) -> #REF! | C13: =IF(ISBLANK($A13), "", VLOOKUP($A13, 入力シート!$A$7:$J$1000, 4, FALSE)) -> #REF! | D13: =IF(ISBLANK($A13), "", VLOOKUP($A13, 入力シート!$A$7:$J$1000, 6, FALSE)) -> #REF! | E13: =IF(ISBLANK($A13), "", VLOOKUP($A13, 入力シート!$A$7:$J$1000, 7, FALSE)) -> #REF! | F13: =IF(ISBLANK($A13), "", VLOOKUP($A13, 入力シート!$A$7:$J$1000, 10, FALSE)) -> #REF! | G13: =IF(ISBLANK($A13), "", VLOOKUP($A13, 入力シート!$A$7:$J$1000, 9, FALSE)) -> #REF! | H13: =IF(ISBLANK($A13), "", VLOOKUP($A13, 入力シート!$A$7:$J$1000, 8, FALSE)) -> #REF!
A15: 6 | B15: =IF(ISBLANK($A15), "", VLOOKUP($A15, 入力シート!$A$7:$J$1000, 3, FALSE)) -> #REF! | C15: =IF(ISBLANK($A15), "", VLOOKUP($A15, 入力シート!$A$7:$J$1000, 4, FALSE)) -> #REF! | D15: =IF(ISBLANK($A15), "", VLOOKUP($A15, 入力シート!$A$7:$J$1000, 6, FALSE)) -> #REF! | E15: =IF(ISBLANK($A15), "", VLOOKUP($A15, 入力シート!$A$7:$J$1000, 7, FALSE)) -> #REF! | F15: =IF(ISBLANK($A15), "", VLOOKUP($A15, 入力シート!$A$7:$J$1000, 10, FALSE)) -> #REF! | G15: =IF(ISBLANK($A15), "", VLOOKUP($A15, 入力シート!$A$7:$J$1000, 9, FALSE)) -> #REF! | H15: =IF(ISBLANK($A15), "", VLOOKUP($A15, 入力シート!$A$7:$J$1000, 8, FALSE)) -> #REF!
A17: 7 | B17: =IF(ISBLANK($A17), "", VLOOKUP($A17, 入力シート!$A$7:$J$1000, 3, FALSE)) -> 0 | C17: =IF(ISBLANK($A17), "", VLOOKUP($A17, 入力シート!$A$7:$J$1000, 4, FALSE)) -> 0 | D17: =IF(ISBLANK($A17), "", VLOOKUP($A17, 入力シート!$A$7:$J$1000, 6, FALSE)) -> 0 | E17: =IF(ISBLANK($A17), "", VLOOKUP($A17, 入力シート!$A$7:$J$1000, 7, FALSE)) -> 0 | F17: =IF(ISBLANK($A17), "", VLOOKUP($A17, 入力シート!$A$7:$J$1000, 10, FALSE)) -> 0 | G17: =IF(ISBLANK($A17), "", VLOOKUP($A17, 入力シート!$A$7:$J$1000, 9, FALSE)) -> 0 | H17: =IF(ISBLANK($A17), "", VLOOKUP($A17, 入力シート!$A$7:$J$1000, 8, FALSE)) -> 0
A19: 8 | B19: =IF(ISBLANK($A19), "", VLOOKUP($A19, 入力シート!$A$7:$J$1000, 3, FALSE)) -> 0 | C19: =IF(ISBLANK($A19), "", VLOOKUP($A19, 入力シート!$A$7:$J$1000, 4, FALSE)) -> 0 | D19: =IF(ISBLANK($A19), "", VLOOKUP($A19, 入力シート!$A$7:$J$1000, 6, FALSE)) -> 0 | E19: =IF(ISBLANK($A19), "", VLOOKUP($A19, 入力シート!$A$7:$J$1000, 7, FALSE)) -> 0 | F19: =IF(ISBLANK($A19), "", VLOOKUP($A19, 入力シート!$A$7:$J$1000, 10, FALSE)) -> 0 | G19: =IF(ISBLANK($A19), "", VLOOKUP($A19, 入力シート!$A$7:$J$1000, 9, FALSE)) -> 0 | H19: =IF(ISBLANK($A19), "", VLOOKUP($A19, 入力シート!$A$7:$J$1000, 8, FALSE)) -> 0
A21: 9 | B21: =IF(ISBLANK($A21), "", VLOOKUP($A21, 入力シート!$A$7:$J$1000, 3, FALSE)) -> 0 | C21: =IF(ISBLANK($A21), "", VLOOKUP($A21, 入力シート!$A$7:$J$1000, 4, FALSE)) -> 0 | D21: =IF(ISBLANK($A21), "", VLOOKUP($A21, 入力シート!$A$7:$J$1000, 6, FALSE)) -> 0 | E21: =IF(ISBLANK($A21), "", VLOOKUP($A21, 入力シート!$A$7:$J$1000, 7, FALSE)) -> 0 | F21: =IF(ISBLANK($A21), "", VLOOKUP($A21, 入力シート!$A$7:$J$1000, 10, FALSE)) -> 0 | G21: =IF(ISBLANK($A21), "", VLOOKUP($A21, 入力シート!$A$7:$J$1000, 9, FALSE)) -> 0 | H21: =IF(ISBLANK($A21), "", VLOOKUP($A21, 入力シート!$A$7:$J$1000, 8, FALSE)) -> 0
A23: 10 | B23: =IF(ISBLANK($A23), "", VLOOKUP($A23, 入力シート!$A$7:$J$1000, 3, FALSE)) -> 0 | C23: =IF(ISBLANK($A23), "", VLOOKUP($A23, 入力シート!$A$7:$J$1000, 4, FALSE)) -> 0 | D23: =IF(ISBLANK($A23), "", VLOOKUP($A23, 入力シート!$A$7:$J$1000, 6, FALSE)) -> 0 | E23: =IF(ISBLANK($A23), "", VLOOKUP($A23, 入力シート!$A$7:$J$1000, 7, FALSE)) -> 0 | F23: =IF(ISBLANK($A23), "", VLOOKUP($A23, 入力シート!$A$7:$J$1000, 10, FALSE)) -> 0 | G23: =IF(ISBLANK($A23), "", VLOOKUP($A23, 入力シート!$A$7:$J$1000, 9, FALSE)) -> 0 | H23: =IF(ISBLANK($A23), "", VLOOKUP($A23, 入力シート!$A$7:$J$1000, 8, FALSE)) -> 0
A25: 11 | B25: =IF(ISBLANK($A25), "", VLOOKUP($A25, 入力シート!$A$7:$J$1000, 3, FALSE)) -> 0 | C25: =IF(ISBLANK($A25), "", VLOOKUP($A25, 入力シート!$A$7:$J$1000, 4, FALSE)) -> 0 | D25: =IF(ISBLANK($A25), "", VLOOKUP($A25, 入力シート!$A$7:$J$1000, 6, FALSE)) -> 0 | E25: =IF(ISBLANK($A25), "", VLOOKUP($A25, 入力シート!$A$7:$J$1000, 7, FALSE)) -> 0 | F25: =IF(ISBLANK($A25), "", VLOOKUP($A25, 入力シート!$A$7:$J$1000, 10, FALSE)) -> 0 | G25: =IF(ISBLANK($A25), "", VLOOKUP($A25, 入力シート!$A$7:$J$1000, 9, FALSE)) -> 0 | H25: =IF(ISBLANK($A25), "", VLOOKUP($A25, 入力シート!$A$7:$J$1000, 8, FALSE)) -> 0
A27: 12 | B27: =IF(ISBLANK($A27), "", VLOOKUP($A27, 入力シート!$A$7:$J$1000, 3, FALSE)) -> 0 | C27: =IF(ISBLANK($A27), "", VLOOKUP($A27, 入力シート!$A$7:$J$1000, 4, FALSE)) -> 0 | D27: =IF(ISBLANK($A27), "", VLOOKUP($A27, 入力シート!$A$7:$J$1000, 6, FALSE)) -> 0 | E27: =IF(ISBLANK($A27), "", VLOOKUP($A27, 入力シート!$A$7:$J$1000, 7, FALSE)) -> 0 | F27: =IF(ISBLANK($A27), "", VLOOKUP($A27, 入力シート!$A$7:$J$1000, 10, FALSE)) -> 0 | G27: =IF(ISBLANK($A27), "", VLOOKUP($A27, 入力シート!$A$7:$J$1000, 9, FALSE)) -> 0 | H27: =IF(ISBLANK($A27), "", VLOOKUP($A27, 入力シート!$A$7:$J$1000, 8, FALSE)) -> 0
... A31: 14 | B31: =IF(ISBLANK($A31), "", VLOOKUP($A31, 入力シート!$A$7:$J$1000, 3, FALSE)) -> 0 | C31: =IF(ISBLANK($A31), "", VLOOKUP($A31, 入力シート!$A$7:$J$1000, 4, FALSE)) -> 0 | D31: =IF(ISBLANK($A31), "", VLOOKUP($A31, 入力シート!$A$7:$J$1000, 6, FALSE)) -> 0 | E31: =IF(ISBLANK($A31), "", VLOOKUP($A31, 入力シート!$A$7:$J$1000, 7, FALSE)) -> 0 | F31: =IF(ISBLANK($A31), "", VLOOKUP($A31, 入力シート!$A$7:$J$1000, 10, FALSE)) -> 0 | G31: =IF(ISBLANK($A31), "", VLOOKUP($A31, 入力シート!$A$7:$J$1000, 9, FALSE)) -> 0 | H31: =IF(ISBLANK($A31), "", VLOOKUP($A31, 入力シート!$A$7:$J$1000, 8, FALSE)) -> 0

Sheet 所有者調書(北)
B1: 土 地 所 有 者 調 書
B3: 土地所在 | C3: 地番 | D3: 地目 | E3: 地積 | F3: 登記 年月日 | G3: 所有者名 | H3: 登記事項証明書(土地)等の住所
H4: 住民登録の住所
A5: 1 | B5: =IF(ISBLANK($A5), "", VLOOKUP($A5, 入力シート!$A$7:$J$1000, 3, FALSE)) -> #REF! | C5: =IF(ISBLANK($A5), "", VLOOKUP($A5, 入力シート!$A$7:$J$1000, 4, FALSE)) -> #REF! | D5: =IF(ISBLANK($A5), "", VLOOKUP($A5, 入力シート!$A$7:$J$1000, 6, FALSE)) -> #REF! | E5: =IF(ISBLANK($A5), "", VLOOKUP($A5, 入力シート!$A$7:$J$1000, 7, FALSE)) -> #REF! | F5: =IF(ISBLANK($A5), "", VLOOKUP($A5, 入力シート!$A$7:$J$1000, 10, FALSE)) -> #REF! | G5: =IF(ISBLANK($A5), "", VLOOKUP($A5, 入力シート!$A$7:$J$1000, 9, FALSE)) -> #REF! | H5: =IF(ISBLANK($A5), "", VLOOKUP($A5, 入力シート!$A$7:$J$1000, 8, FALSE)) -> #REF!
A7: 2 | B7: =IF(ISBLANK($A7), "", VLOOKUP($A7, 入力シート!$A$7:$J$1000, 3, FALSE)) -> #REF! | C7: =IF(ISBLANK($A7), "", VLOOKUP($A7, 入力シート!$A$7:$J$1000, 4, FALSE)) -> #REF! | D7: =IF(ISBLANK($A7), "", VLOOKUP($A7, 入力シート!$A$7:$J$1000, 6, FALSE)) -> #REF! | E7: =IF(ISBLANK($A7), "", VLOOKUP($A7, 入力シート!$A$7:$J$1000, 7, FALSE)) -> #REF! | F7: =IF(ISBLANK($A7), "", VLOOKUP($A7, 入力シート!$A$7:$J$1000, 10, FALSE)) -> #REF! | G7: =IF(ISBLANK($A7), "", VLOOKUP($A7, 入力シート!$A$7:$J$1000, 9, FALSE)) -> #REF! | H7: =IF(ISBLANK($A7), "", VLOOKUP($A7, 入力シート!$A$7:$J$1000, 8, FALSE)) -> #REF!
A9: 3 | B9: =IF(ISBLANK($A9), "", VLOOKUP($A9, 入力シート!$A$7:$J$1000, 3, FALSE)) -> #REF! | C9: =IF(ISBLANK($A9), "", VLOOKUP($A9, 入力シート!$A$7:$J$1000, 4, FALSE)) -> #REF! | D9: =IF(ISBLANK($A9), "", VLOOKUP($A9, 入力シート!$A$7:$J$1000, 6, FALSE)) -> #REF! | E9: =IF(ISBLANK($A9), "", VLOOKUP($A9, 入力シート!$A$7:$J$1000, 7, FALSE)) -> #REF! | F9: =IF(ISBLANK($A9), "", VLOOKUP($A9, 入力シート!$A$7:$J$1000, 10, FALSE)) -> #REF! | G9: =IF(ISBLANK($A9), "", VLOOKUP($A9, 入力シート!$A$7:$J$1000, 9, FALSE)) -> #REF! | H9: =IF(ISBLANK($A9), "", VLOOKUP($A9, 入力シート!$A$7:$J$1000, 8, FALSE)) -> #REF!
A11: 4 | B11: =IF(ISBLANK($A11), "", VLOOKUP($A11, 入力シート!$A$7:$J$1000, 3, FALSE)) -> #REF! | C11: =IF(ISBLANK($A11), "", VLOOKUP($A11, 入力シート!$A$7:$J$1000, 4, FALSE)) -> #REF! | D11: =IF(ISBLANK($A11), "", VLOOKUP($A11, 入力シート!$A$7:$J$1000, 6, FALSE)) -> #REF! | E11: =IF(ISBLANK($A11), "", VLOOKUP($A11, 入力シート!$A$7:$J$1000, 7, FALSE)) -> #REF! | F11: =IF(ISBLANK($A11), "", VLOOKUP($A11, 入力シート!$A$7:$J$1000, 10, FALSE)) -> #REF! | G11: =IF(ISBLANK($A11), "", VLOOKUP($A11, 入力シート!$A$7:$J$1000, 9, FALSE)) -> #REF! | H11: =IF(ISBLANK($A11), "", VLOOKUP($A11, 入力シート!$A$7:$J$1000, 8, FALSE)) -> #REF!
A13: 5 | B13: =IF(ISBLANK($A13), "", VLOOKUP($A13, 入力シート!$A$7:$J$1000, 3, FALSE)) -> #REF! | C13: =IF(ISBLANK($A13), "", VLOOKUP($A13, 入力シート!$A$7:$J$1000, 4, FALSE)) -> #REF! | D13: =IF(ISBLANK($A13), "", VLOOKUP($A13, 入力シート!$A$7:$J$1000, 6, FALSE)) -> #REF! | E13: =IF(ISBLANK($A13), "", VLOOKUP($A13, 入力シート!$A$7:$J$1000, 7, FALSE)) -> #REF! | F13: =IF(ISBLANK($A13), "", VLOOKUP($A13, 入力シート!$A$7:$J$1000, 10, FALSE)) -> #REF! | G13: =IF(ISBLANK($A13), "", VLOOKUP($A13, 入力シート!$A$7:$J$1000, 9, FALSE)) -> #REF! | H13: =IF(ISBLANK($A13), "", VLOOKUP($A13, 入力シート!$A$7:$J$1000, 8, FALSE)) -> #REF!
A15: 6 | B15: =IF(ISBLANK($A15), "", VLOOKUP($A15, 入力シート!$A$7:$J$1000, 3, FALSE)) -> #REF! | C15: =IF(ISBLANK($A15), "", VLOOKUP($A15, 入力シート!$A$7:$J$1000, 4, FALSE)) -> #REF! | D15: =IF(ISBLANK($A15), "", VLOOKUP($A15, 入力シート!$A$7:$J$1000, 6, FALSE)) -> #REF! | E15: =IF(ISBLANK($A15), "", VLOOKUP($A15, 入力シート!$A$7:$J$1000, 7, FALSE)) -> #REF! | F15: =IF(ISBLANK($A15), "", VLOOKUP($A15, 入力シート!$A$7:$J$1000, 10, FALSE)) -> #REF! | G15: =IF(ISBLANK($A15), "", VLOOKUP($A15, 入力シート!$A$7:$J$1000, 9, FALSE)) -> #REF! | H15: =IF(ISBLANK($A15), "", VLOOKUP($A15, 入力シート!$A$7:$J$1000, 8, FALSE)) -> #REF!
A17: 7 | B17: =IF(ISBLANK($A17), "", VLOOKUP($A17, 入力シート!$A$7:$J$1000, 3, FALSE)) -> 0 | C17: =IF(ISBLANK($A17), "", VLOOKUP($A17, 入力シート!$A$7:$J$1000, 4, FALSE)) -> 0 | D17: =IF(ISBLANK($A17), "", VLOOKUP($A17, 入力シート!$A$7:$J$1000, 6, FALSE)) -> 0 | E17: =IF(ISBLANK($A17), "", VLOOKUP($A17, 入力シート!$A$7:$J$1000, 7, FALSE)) -> 0 | F17: =IF(ISBLANK($A17), "", VLOOKUP($A17, 入力シート!$A$7:$J$1000, 10, FALSE)) -> 0 | G17: =IF(ISBLANK($A17), "", VLOOKUP($A17, 入力シート!$A$7:$J$1000, 9, FALSE)) -> 0 | H17: =IF(ISBLANK($A17), "", VLOOKUP($A17, 入力シート!$A$7:$J$1000, 8, FALSE)) -> 0
A19: 8 | B19: =IF(ISBLANK($A19), "", VLOOKUP($A19, 入力シート!$A$7:$J$1000, 3, FALSE)) -> 0 | C19: =IF(ISBLANK($A19), "", VLOOKUP($A19, 入力シート!$A$7:$J$1000, 4, FALSE)) -> 0 | D19: =IF(ISBLANK($A19), "", VLOOKUP($A19, 入力シート!$A$7:$J$1000, 6, FALSE)) -> 0 | E19: =IF(ISBLANK($A19), "", VLOOKUP($A19, 入力シート!$A$7:$J$1000, 7, FALSE)) -> 0 | F19: =IF(ISBLANK($A19), "", VLOOKUP($A19, 入力シート!$A$7:$J$1000, 10, FALSE)) -> 0 | G19: =IF(ISBLANK($A19), "", VLOOKUP($A19, 入力シート!$A$7:$J$1000, 9, FALSE)) -> 0 | H19: =IF(ISBLANK($A19), "", VLOOKUP($A19, 入力シート!$A$7:$J$1000, 8, FALSE)) -> 0
A21: 9 | B21: =IF(ISBLANK($A21), "", VLOOKUP($A21, 入力シート!$A$7:$J$1000, 3, FALSE)) -> 0 | C21: =IF(ISBLANK($A21), "", VLOOKUP($A21, 入力シート!$A$7:$J$1000, 4, FALSE)) -> 0 | D21: =IF(ISBLANK($A21), "", VLOOKUP($A21, 入力シート!$A$7:$J$1000, 6, FALSE)) -> 0 | E21: =IF(ISBLANK($A21), "", VLOOKUP($A21, 入力シート!$A$7:$J$1000, 7, FALSE)) -> 0 | F21: =IF(ISBLANK($A21), "", VLOOKUP($A21, 入力シート!$A$7:$J$1000, 10, FALSE)) -> 0 | G21: =IF(ISBLANK($A21), "", VLOOKUP($A21, 入力シート!$A$7:$J$1000, 9, FALSE)) -> 0 | H21: =IF(ISBLANK($A21), "", VLOOKUP($A21, 入力シート!$A$7:$J$1000, 8, FALSE)) -> 0
A23: 10 | B23: =IF(ISBLANK($A23), "", VLOOKUP($A23, 入力シート!$A$7:$J$1000, 3, FALSE)) -> 0 | C23: =IF(ISBLANK($A23), "", VLOOKUP($A23, 入力シート!$A$7:$J$1000, 4, FALSE)) -> 0 | D23: =IF(ISBLANK($A23), "", VLOOKUP($A23, 入力シート!$A$7:$J$1000, 6, FALSE)) -> 0 | E23: =IF(ISBLANK($A23), "", VLOOKUP($A23, 入力シート!$A$7:$J$1000, 7, FALSE)) -> 0 | F23: =IF(ISBLANK($A23), "", VLOOKUP($A23, 入力シート!$A$7:$J$1000, 10, FALSE)) -> 0 | G23: =IF(ISBLANK($A23), "", VLOOKUP($A23, 入力シート!$A$7:$J$1000, 9, FALSE)) -> 0 | H23: =IF(ISBLANK($A23), "", VLOOKUP($A23, 入力シート!$A$7:$J$1000, 8, FALSE)) -> 0
A25: 11 | B25: =IF(ISBLANK($A25), "", VLOOKUP($A25, 入力シート!$A$7:$J$1000, 3, FALSE)) -> 0 | C25: =IF(ISBLANK($A25), "", VLOOKUP($A25, 入力シート!$A$7:$J$1000, 4, FALSE)) -> 0 | D25: =IF(ISBLANK($A25), "", VLOOKUP($A25, 入力シート!$A$7:$J$1000, 6, FALSE)) -> 0 | E25: =IF(ISBLANK($A25), "", VLOOKUP($A25, 入力シート!$A$7:$J$1000, 7, FALSE)) -> 0 | F25: =IF(ISBLANK($A25), "", VLOOKUP($A25, 入力シート!$A$7:$J$1000, 10, FALSE)) -> 0 | G25: =IF(ISBLANK($A25), "", VLOOKUP($A25, 入力シート!$A$7:$J$1000, 9, FALSE)) -> 0 | H25: =IF(ISBLANK($A25), "", VLOOKUP($A25, 入力シート!$A$7:$J$1000, 8, FALSE)) -> 0
A27: 12 | B27: =IF(ISBLANK($A27), "", VLOOKUP($A27, 入力シート!$A$7:$J$1000, 3, FALSE)) -> 0 | C27: =IF(ISBLANK($A27), "", VLOOKUP($A27, 入力シート!$A$7:$J$1000, 4, FALSE)) -> 0 | D27: =IF(ISBLANK($A27), "", VLOOKUP($A27, 入力シート!$A$7:$J$1000, 6, FALSE)) -> 0 | E27: =IF(ISBLANK($A27), "", VLOOKUP($A27, 入力シート!$A$7:$J$1000, 7, FALSE)) -> 0 | F27: =IF(ISBLANK($A27), "", VLOOKUP($A27, 入力シート!$A$7:$J$1000, 10, FALSE)) -> 0 | G27: =IF(ISBLANK($A27), "", VLOOKUP($A27, 入力シート!$A$7:$J$1000, 9, FALSE)) -> 0 | H27: =IF(ISBLANK($A27), "", VLOOKUP($A27, 入力シート!$A$7:$J$1000, 8, FALSE)) -> 0
... A31: 14 | B31: =IF(ISBLANK($A31), "", VLOOKUP($A31, 入力シート!$A$7:$J$1000, 3, FALSE)) -> 0 | C31: =IF(ISBLANK($A31), "", VLOOKUP($A31, 入力シート!$A$7:$J$1000, 4, FALSE)) -> 0 | D31: =IF(ISBLANK($A31), "", VLOOKUP($A31, 入力シート!$A$7:$J$1000, 6, FALSE)) -> 0 | E31: =IF(ISBLANK($A31), "", VLOOKUP($A31, 入力シート!$A$7:$J$1000, 7, FALSE)) -> 0 | F31: =IF(ISBLANK($A31), "", VLOOKUP($A31, 入力シート!$A$7:$J$1000, 10, FALSE)) -> 0 | G31: =IF(ISBLANK($A31), "", VLOOKUP($A31, 入力シート!$A$7:$J$1000, 9, FALSE)) -> 0 | H31: =IF(ISBLANK($A31), "", VLOOKUP($A31, 入力シート!$A$7:$J$1000, 8, FALSE)) -> 0

Sheet 所有者調書(品川)
B1: 土 地 所 有 者 調 書
B3: 土地所在 | C3: 地番 | D3: 地目 | E3: 地積 | F3: 登記 年月日 | G3: 所有者 | H3: 登記事項証明書等の住所
H4: 住民登録の住所
A5: 1 | B5: =IF(ISBLANK($A5), "", VLOOKUP($A5, 入力シート!$A$7:$J$1000, 3, FALSE)) -> #REF! | C5: =IF(ISBLANK($A5), "", VLOOKUP($A5, 入力シート!$A$7:$J$1000, 4, FALSE)) -> #REF! | D5: =IF(ISBLANK($A5), "", VLOOKUP($A5, 入力シート!$A$7:$J$1000, 6, FALSE)) -> #REF! | E5: =IF(ISBLANK($A5), "", VLOOKUP($A5, 入力シート!$A$7:$J$1000, 7, FALSE)) -> #REF! | F5: =IF(ISBLANK($A5), "", VLOOKUP($A5, 入力シート!$A$7:$J$1000, 10, FALSE)) -> #REF! | G5: =IF(ISBLANK($A5), "", VLOOKUP($A5, 入力シート!$A$7:$J$1000, 9, FALSE)) -> #REF! | H5: =IF(ISBLANK($A5), "", VLOOKUP($A5, 入力シート!$A$7:$J$1000, 8, FALSE)) -> #REF!
A7: 2 | B7: =IF(ISBLANK($A7), "", VLOOKUP($A7, 入力シート!$A$7:$J$1000, 3, FALSE)) -> #REF! | C7: =IF(ISBLANK($A7), "", VLOOKUP($A7, 入力シート!$A$7:$J$1000, 4, FALSE)) -> #REF! | D7: =IF(ISBLANK($A7), "", VLOOKUP($A7, 入力シート!$A$7:$J$1000, 6, FALSE)) -> #REF! | E7: =IF(ISBLANK($A7), "", VLOOKUP($A7, 入力シート!$A$7:$J$1000, 7, FALSE)) -> #REF! | F7: =IF(ISBLANK($A7), "", VLOOKUP($A7, 入力シート!$A$7:$J$1000, 10, FALSE)) -> #REF! | G7: =IF(ISBLANK($A7), "", VLOOKUP($A7, 入力シート!$A$7:$J$1000, 9, FALSE)) -> #REF! | H7: =IF(ISBLANK($A7), "", VLOOKUP($A7, 入力シート!$A$7:$J$1000, 8, FALSE)) -> #REF!
A9: 3 | B9: =IF(ISBLANK($A9), "", VLOOKUP($A9, 入力シート!$A$7:$J$1000, 3, FALSE)) -> #REF! | C9: =IF(ISBLANK($A9), "", VLOOKUP($A9, 入力シート!$A$7:$J$1000, 4, FALSE)) -> #REF! | D9: =IF(ISBLANK($A9), "", VLOOKUP($A9, 入力シート!$A$7:$J$1000, 6, FALSE)) -> #REF! | E9: =IF(ISBLANK($A9), "", VLOOKUP($A9, 入力シート!$A$7:$J$1000, 7, FALSE)) -> #REF! | F9: =IF(ISBLANK($A9), "", VLOOKUP($A9, 入力シート!$A$7:$J$1000, 10, FALSE)) -> #REF! | G9: =IF(ISBLANK($A9), "", VLOOKUP($A9, 入力シート!$A$7:$J$1000, 9, FALSE)) -> #REF! | H9: =IF(ISBLANK($A9), "", VLOOKUP($A9, 入力シート!$A$7:$J$1000, 8, FALSE)) -> #REF!
A11: 4 | B11: =IF(ISBLANK($A11), "", VLOOKUP($A11, 入力シート!$A$7:$J$1000, 3, FALSE)) -> #REF! | C11: =IF(ISBLANK($A11), "", VLOOKUP($A11, 入力シート!$A$7:$J$1000, 4, FALSE)) -> #REF! | D11: =IF(ISBLANK($A11), "", VLOOKUP($A11, 入力シート!$A$7:$J$1000, 6, FALSE)) -> #REF! | E11: =IF(ISBLANK($A11), "", VLOOKUP($A11, 入力シート!$A$7:$J$1000, 7, FALSE)) -> #REF! | F11: =IF(ISBLANK($A11), "", VLOOKUP($A11, 入力シート!$A$7:$J$1000, 10, FALSE)) -> #REF! | G11: =IF(ISBLANK($A11), "", VLOOKUP($A11, 入力シート!$A$7:$J$1000, 9, FALSE)) -> #REF! | H11: =IF(ISBLANK($A11), "", VLOOKUP($A11, 入力シート!$A$7:$J$1000, 8, FALSE)) -> #REF!
A13: 5 | B13: =IF(ISBLANK($A13), "", VLOOKUP($A13, 入力シート!$A$7:$J$1000, 3, FALSE)) -> #REF! | C13: =IF(ISBLANK($A13), "", VLOOKUP($A13, 入力シート!$A$7:$J$1000, 4, FALSE)) -> #REF! | D13: =IF(ISBLANK($A13), "", VLOOKUP($A13, 入力シート!$A$7:$J$1000, 6, FALSE)) -> #REF! | E13: =IF(ISBLANK($A13), "", VLOOKUP($A13, 入力シート!$A$7:$J$1000, 7, FALSE)) -> #REF! | F13: =IF(ISBLANK($A13), "", VLOOKUP($A13, 入力シート!$A$7:$J$1000, 10, FALSE)) -> #REF! | G13: =IF(ISBLANK($A13), "", VLOOKUP($A13, 入力シート!$A$7:$J$1000, 9, FALSE)) -> #REF! | H13: =IF(ISBLANK($A13), "", VLOOKUP($A13, 入力シート!$A$7:$J$1000, 8, FALSE)) -> #REF!
A15: 6 | B15: =IF(ISBLANK($A15), "", VLOOKUP($A15, 入力シート!$A$7:$J$1000, 3, FALSE)) -> #REF! | C15: =IF(ISBLANK($A15), "", VLOOKUP($A15, 入力シート!$A$7:$J$1000, 4, FALSE)) -> #REF! | D15: =IF(ISBLANK($A15), "", VLOOKUP($A15, 入力シート!$A$7:$J$1000, 6, FALSE)) -> #REF! | E15: =IF(ISBLANK($A15), "", VLOOKUP($A15, 入力シート!$A$7:$J$1000, 7, FALSE)) -> #REF! | F15: =IF(ISBLANK($A15), "", VLOOKUP($A15, 入力シート!$A$7:$J$1000, 10, FALSE)) -> #REF! | G15: =IF(ISBLANK($A15), "", VLOOKUP($A15, 入力シート!$A$7:$J$1000, 9, FALSE)) -> #REF! | H15: =IF(ISBLANK($A15), "", VLOOKUP($A15, 入力シート!$A$7:$J$1000, 8, FALSE)) -> #REF!
A17: 7 | B17: =IF(ISBLANK($A17), "", VLOOKUP($A17, 入力シート!$A$7:$J$1000, 3, FALSE)) -> 0 | C17: =IF(ISBLANK($A17), "", VLOOKUP($A17, 入力シート!$A$7:$J$1000, 4, FALSE)) -> 0 | D17: =IF(ISBLANK($A17), "", VLOOKUP($A17, 入力シート!$A$7:$J$1000, 6, FALSE)) -> 0 | E17: =IF(ISBLANK($A17), "", VLOOKUP($A17, 入力シート!$A$7:$J$1000, 7, FALSE)) -> 0 | F17: =IF(ISBLANK($A17), "", VLOOKUP($A17, 入力シート!$A$7:$J$1000, 10, FALSE)) -> 0 | G17: =IF(ISBLANK($A17), "", VLOOKUP($A17, 入力シート!$A$7:$J$1000, 9, FALSE)) -> 0 | H17: =IF(ISBLANK($A17), "", VLOOKUP($A17, 入力シート!$A$7:$J$1000, 8, FALSE)) -> 0
A19: 8 | B19: =IF(ISBLANK($A19), "", VLOOKUP($A19, 入力シート!$A$7:$J$1000, 3, FALSE)) -> 0 | C19: =IF(ISBLANK($A19), "", VLOOKUP($A19, 入力シート!$A$7:$J$1000, 4, FALSE)) -> 0 | D19: =IF(ISBLANK($A19), "", VLOOKUP($A19, 入力シート!$A$7:$J$1000, 6, FALSE)) -> 0 | E19: =IF(ISBLANK($A19), "", VLOOKUP($A19, 入力シート!$A$7:$J$1000, 7, FALSE)) -> 0 | F19: =IF(ISBLANK($A19), "", VLOOKUP($A19, 入力シート!$A$7:$J$1000, 10, FALSE)) -> 0 | G19: =IF(ISBLANK($A19), "", VLOOKUP($A19, 入力シート!$A$7:$J$1000, 9, FALSE)) -> 0 | H19: =IF(ISBLANK($A19), "", VLOOKUP($A19, 入力シート!$A$7:$J$1000, 8, FALSE)) -> 0
A21: 9 | B21: =IF(ISBLANK($A21), "", VLOOKUP($A21, 入力シート!$A$7:$J$1000, 3, FALSE)) -> 0 | C21: =IF(ISBLANK($A21), "", VLOOKUP($A21, 入力シート!$A$7:$J$1000, 4, FALSE)) -> 0 | D21: =IF(ISBLANK($A21), "", VLOOKUP($A21, 入力シート!$A$7:$J$1000, 6, FALSE)) -> 0 | E21: =IF(ISBLANK($A21), "", VLOOKUP($A21, 入力シート!$A$7:$J$1000, 7, FALSE)) -> 0 | F21: =IF(ISBLANK($A21), "", VLOOKUP($A21, 入力シート!$A$7:$J$1000, 10, FALSE)) -> 0 | G21: =IF(ISBLANK($A21), "", VLOOKUP($A21, 入力シート!$A$7:$J$1000, 9, FALSE)) -> 0 | H21: =IF(ISBLANK($A21), "", VLOOKUP($A21, 入力シート!$A$7:$J$1000, 8, FALSE)) -> 0
A23: 10 | B23: =IF(ISBLANK($A23), "", VLOOKUP($A23, 入力シート!$A$7:$J$1000, 3, FALSE)) -> 0 | C23: =IF(ISBLANK($A23), "", VLOOKUP($A23, 入力シート!$A$7:$J$1000, 4, FALSE)) -> 0 | D23: =IF(ISBLANK($A23), "", VLOOKUP($A23, 入力シート!$A$7:$J$1000, 6, FALSE)) -> 0 | E23: =IF(ISBLANK($A23), "", VLOOKUP($A23, 入力シート!$A$7:$J$1000, 7, FALSE)) -> 0 | F23: =IF(ISBLANK($A23), "", VLOOKUP($A23, 入力シート!$A$7:$J$1000, 10, FALSE)) -> 0 | G23: =IF(ISBLANK($A23), "", VLOOKUP($A23, 入力シート!$A$7:$J$1000, 9, FALSE)) -> 0 | H23: =IF(ISBLANK($A23), "", VLOOKUP($A23, 入力シート!$A$7:$J$1000, 8, FALSE)) -> 0
A25: 11 | B25: =IF(ISBLANK($A25), "", VLOOKUP($A25, 入力シート!$A$7:$J$1000, 3, FALSE)) -> 0 | C25: =IF(ISBLANK($A25), "", VLOOKUP($A25, 入力シート!$A$7:$J$1000, 4, FALSE)) -> 0 | D25: =IF(ISBLANK($A25), "", VLOOKUP($A25, 入力シート!$A$7:$J$1000, 6, FALSE)) -> 0 | E25: =IF(ISBLANK($A25), "", VLOOKUP($A25, 入力シート!$A$7:$J$1000, 7, FALSE)) -> 0 | F25: =IF(ISBLANK($A25), "", VLOOKUP($A25, 入力シート!$A$7:$J$1000, 10, FALSE)) -> 0 | G25: =IF(ISBLANK($A25), "", VLOOKUP($A25, 入力シート!$A$7:$J$1000, 9, FALSE)) -> 0 | H25: =IF(ISBLANK($A25), "", VLOOKUP($A25, 入力シート!$A$7:$J$1000, 8, FALSE)) -> 0
A27: 12 | B27: =IF(ISBLANK($A27), "", VLOOKUP($A27, 入力シート!$A$7:$J$1000, 3, FALSE)) -> 0 | C27: =IF(ISBLANK($A27), "", VLOOKUP($A27, 入力シート!$A$7:$J$1000, 4, FALSE)) -> 0 | D27: =IF(ISBLANK($A27), "", VLOOKUP($A27, 入力シート!$A$7:$J$1000, 6, FALSE)) -> 0 | E27: =IF(ISBLANK($A27), "", VLOOKUP($A27, 入力シート!$A$7:$J$1000, 7, FALSE)) -> 0 | F27: =IF(ISBLANK($A27), "", VLOOKUP($A27, 入力シート!$A$7:$J$1000, 10, FALSE)) -> 0 | G27: =IF(ISBLANK($A27), "", VLOOKUP($A27, 入力シート!$A$7:$J$1000, 9, FALSE)) -> 0 | H27: =IF(ISBLANK($A27), "", VLOOKUP($A27, 入力シート!$A$7:$J$1000, 8, FALSE)) -> 0
A29: 13 | B29: =IF(ISBLANK($A29), "", VLOOKUP($A29, 入力シート!$A$7:$J$1000, 3, FALSE)) -> 0 | C29: =IF(ISBLANK($A29), "", VLOOKUP($A29, 入力シート!$A$7:$J$1000, 4, FALSE)) -> 0 | D29: =IF(ISBLANK($A29), "", VLOOKUP($A29, 入力シート!$A$7:$J$1000, 6, FALSE)) -> 0 | E29: =IF(ISBLANK($A29), "", VLOOKUP($A29, 入力シート!$A$7:$J$1000, 7, FALSE)) -> 0 | F29: =IF(ISBLANK($A29), "", VLOOKUP($A29, 入力シート!$A$7:$J$1000, 10, FALSE)) -> 0 | G29: =IF(ISBLANK($A29), "", VLOOKUP($A29, 入力シート!$A$7:$J$1000, 9, FALSE)) -> 0 | H29: =IF(ISBLANK($A29), "", VLOOKUP($A29, 入力シート!$A$7:$J$1000, 8, FALSE)) -> 0
B31: =IF(ISBLANK($A31), "", VLOOKUP($A31, 入力シート!$A$7:$J$1000, 3, FALSE)) | C31: =IF(ISBLANK($A31), "", VLOOKUP($A31, 入力シート!$A$7:$J$1000, 4, FALSE)) | D31: =IF(ISBLANK($A31), "", VLOOKUP($A31, 入力シート!$A$7:$J$1000, 6, FALSE)) | E31: =IF(ISBLANK($A31), "", VLOOKUP($A31, 入力シート!$A$7:$J$1000, 7, FALSE)) | F31: =IF(ISBLANK($A31), "", VLOOKUP($A31, 入力シート!$A$7:$J$1000, 10, FALSE)) | G31: =IF(ISBLANK($A31), "", VLOOKUP($A31, 入力シート!$A$7:$J$1000, 9, FALSE)) | H31: =IF(ISBLANK($A31), "", VLOOKUP($A31, 入力シート!$A$7:$J$1000, 8, FALSE))

Sheet 所有者調書(新宿)
B1: 土 地 所 有 者 調 書 ・ 立 会 同 意 確 認 書
B3: 土地の所在 | C3: 地番 | D3: 地目 | E3: 地積(㎡) | F3: 所有者氏名 | G3: 登記事項証明書 上の住所 | H3: 現住所 | I3: 電話番号 | J3: 立会同意 の有無
A4: 1 | B4: =IF(ISBLANK($A4), "", VLOOKUP($A4, 入力シート!$A$7:$J$1000, 3, FALSE)) -> #REF! | C4: =IF(ISBLANK($A4), "", VLOOKUP($A4, 入力シート!$A$7:$J$1000, 4, FALSE)) -> #REF! | D4: =IF(ISBLANK($A4), "", VLOOKUP($A4, 入力シート!$A$7:$J$1000, 6, FALSE)) -> #REF! | E4: =IF(ISBLANK($A4), "", VLOOKUP($A4, 入力シート!$A$7:$J$1000, 7, FALSE)) -> #REF! | F4: =IF(ISBLANK($A4), "", VLOOKUP($A4, 入力シート!$A$7:$J$1000, 9, FALSE)) -> #REF! | G4: =IF(ISBLANK($A4), "", VLOOKUP($A4, 入力シート!$A$7:$J$1000, 8, FALSE)) -> #REF!
A5: 2 | B5: =IF(ISBLANK($A5), "", VLOOKUP($A5, 入力シート!$A$7:$J$1000, 3, FALSE)) -> #REF! | C5: =IF(ISBLANK($A5), "", VLOOKUP($A5, 入力シート!$A$7:$J$1000, 4, FALSE)) -> #REF! | D5: =IF(ISBLANK($A5), "", VLOOKUP($A5, 入力シート!$A$7:$J$1000, 6, FALSE)) -> #REF! | E5: =IF(ISBLANK($A5), "", VLOOKUP($A5, 入力シート!$A$7:$J$1000, 7, FALSE)) -> #REF! | F5: =IF(ISBLANK($A5), "", VLOOKUP($A5, 入力シート!$A$7:$J$1000, 9, FALSE)) -> #REF! | G5: =IF(ISBLANK($A5), "", VLOOKUP($A5, 入力シート!$A$7:$J$1000, 8, FALSE)) -> #REF!
A6: 3 | B6: =IF(ISBLANK($A6), "", VLOOKUP($A6, 入力シート!$A$7:$J$1000, 3, FALSE)) -> #REF! | C6: =IF(ISBLANK($A6), "", VLOOKUP($A6, 入力シート!$A$7:$J$1000, 4, FALSE)) -> #REF! | D6: =IF(ISBLANK($A6), "", VLOOKUP($A6, 入力シート!$A$7:$J$1000, 6, FALSE)) -> #REF! | E6: =IF(ISBLANK($A6), "", VLOOKUP($A6, 入力シート!$A$7:$J$1000, 7, FALSE)) -> #REF! | F6: =IF(ISBLANK($A6), "", VLOOKUP($A6, 入力シート!$A$7:$J$1000, 9, FALSE)) -> #REF! | G6: =IF(ISBLANK($A6), "", VLOOKUP($A6, 入力シート!$A$7:$J$1000, 8, FALSE)) -> #REF!
A7: 4 | B7: =IF(ISBLANK($A7), "", VLOOKUP($A7, 入力シート!$A$7:$J$1000, 3, FALSE)) -> #REF! | C7: =IF(ISBLANK($A7), "", VLOOKUP($A7, 入力シート!$A$7:$J$1000, 4, FALSE)) -> #REF! | D7: =IF(ISBLANK($A7), "", VLOOKUP($A7, 入力シート!$A$7:$J$1000, 6, FALSE)) -> #REF! | E7: =IF(ISBLANK($A7), "", VLOOKUP($A7, 入力シート!$A$7:$J$1000, 7, FALSE)) -> #REF! | F7: =IF(ISBLANK($A7), "", VLOOKUP($A7, 入力シート!$A$7:$J$1000, 9, FALSE)) -> #REF! | G7: =IF(ISBLANK($A7), "", VLOOKUP($A7, 入力シート!$A$7:$J$1000, 8, FALSE)) -> #REF!
A8: 5 | B8: =IF(ISBLANK($A8), "", VLOOKUP($A8, 入力シート!$A$7:$J$1000, 3, FALSE)) -> #REF! | C8: =IF(ISBLANK($A8), "", VLOOKUP($A8, 入力シート!$A$7:$J$1000, 4, FALSE)) -> #REF! | D8: =IF(ISBLANK($A8), "", VLOOKUP($A8, 入力シート!$A$7:$J$1000, 6, FALSE)) -> #REF! | E8: =IF(ISBLANK($A8), "", VLOOKUP($A8, 入力シート!$A$7:$J$1000, 7, FALSE)) -> #REF! | F8: =IF(ISBLANK($A8), "", VLOOKUP($A8, 入力シート!$A$7:$J$1000, 9, FALSE)) -> #REF! | G8: =IF(ISBLANK($A8), "", VLOOKUP($A8, 入力シート!$A$7:$J$1000, 8, FALSE)) -> #REF!
A9: 6 | B9: =IF(ISBLANK($A9), "", VLOOKUP($A9, 入力シート!$A$7:$J$1000, 3, FALSE)) -> #REF! | C9: =IF(ISBLANK($A9), "", VLOOKUP($A9, 入力シート!$A$7:$J$1000, 4, FALSE)) -> #REF! | D9: =IF(ISBLANK($A9), "", VLOOKUP($A9, 入力シート!$A$7:$J$1000, 6, FALSE)) -> #REF! | E9: =IF(ISBLANK($A9), "", VLOOKUP($A9, 入力シート!$A$7:$J$1000, 7, FALSE)) -> #REF! | F9: =IF(ISBLANK($A9), "", VLOOKUP($A9, 入力シート!$A$7:$J$1000, 9, FALSE)) -> #REF! | G9: =IF(ISBLANK($A9), "", VLOOKUP($A9, 入力シート!$A$7:$J$1000, 8, FALSE)) -> #REF!
A10: 7 | B10: =IF(ISBLANK($A10), "", VLOOKUP($A10, 入力シート!$A$7:$J$1000, 3, FALSE)) -> 0 | C10: =IF(ISBLANK($A10), "", VLOOKUP($A10, 入力シート!$A$7:$J$1000, 4, FALSE)) -> 0 | D10: =IF(ISBLANK($A10), "", VLOOKUP($A10, 入力シート!$A$7:$J$1000, 6, FALSE)) -> 0 | E10: =IF(ISBLANK($A10), "", VLOOKUP($A10, 入力シート!$A$7:$J$1000, 7, FALSE)) -> 0 | F10: =IF(ISBLANK($A10), "", VLOOKUP($A10, 入力シート!$A$7:$J$1000, 9, FALSE)) -> 0 | G10: =IF(ISBLANK($A10), "", VLOOKUP($A10, 入力シート!$A$7:$J$1000, 8, FALSE)) -> 0
A11: 8 | B11: =IF(ISBLANK($A11), "", VLOOKUP($A11, 入力シート!$A$7:$J$1000, 3, FALSE)) -> 0 | C11: =IF(ISBLANK($A11), "", VLOOKUP($A11, 入力シート!$A$7:$J$1000, 4, FALSE)) -> 0 | D11: =IF(ISBLANK($A11), "", VLOOKUP($A11, 入力シート!$A$7:$J$1000, 6, FALSE)) -> 0 | E11: =IF(ISBLANK($A11), "", VLOOKUP($A11, 入力シート!$A$7:$J$1000, 7, FALSE)) -> 0 | F11: =IF(ISBLANK($A11), "", VLOOKUP($A11, 入力シート!$A$7:$J$1000, 9, FALSE)) -> 0 | G11: =IF(ISBLANK($A11), "", VLOOKUP($A11, 入力シート!$A$7:$J$1000, 8, FALSE)) -> 0
A12: 9 | B12: =IF(ISBLANK($A12), "", VLOOKUP($A12, 入力シート!$A$7:$J$1000, 3, FALSE)) -> 0 | C12: =IF(ISBLANK($A12), "", VLOOKUP($A12, 入力シート!$A$7:$J$1000, 4, FALSE)) -> 0 | D12: =IF(ISBLANK($A12), "", VLOOKUP($A12, 入力シート!$A$7:$J$1000, 6, FALSE)) -> 0 | E12: =IF(ISBLANK($A12), "", VLOOKUP($A12, 入力シート!$A$7:$J$1000, 7, FALSE)) -> 0 | F12: =IF(ISBLANK($A12), "", VLOOKUP($A12, 入力シート!$A$7:$J$1000, 9, FALSE)) -> 0 | G12: =IF(ISBLANK($A12), "", VLOOKUP($A12, 入力シート!$A$7:$J$1000, 8, FALSE)) -> 0
A13: 10 | B13: =IF(ISBLANK($A13), "", VLOOKUP($A13, 入力シート!$A$7:$J$1000, 3, FALSE)) -> 0 | C13: =IF(ISBLANK($A13), "", VLOOKUP($A13, 入力シート!$A$7:$J$1000, 4, FALSE)) -> 0 | D13: =IF(ISBLANK($A13), "", VLOOKUP($A13, 入力シート!$A$7:$J$1000, 6, FALSE)) -> 0 | E13: =IF(ISBLANK($A13), "", VLOOKUP($A13, 入力シート!$A$7:$J$1000, 7, FALSE)) -> 0 | F13: =IF(ISBLANK($A13), "", VLOOKUP($A13, 入力シート!$A$7:$J$1000, 9, FALSE)) -> 0 | G13: =IF(ISBLANK($A13), "", VLOOKUP($A13, 入力シート!$A$7:$J$1000, 8, FALSE)) -> 0
A14: 11 | B14: =IF(ISBLANK($A14), "", VLOOKUP($A14, 入力シート!$A$7:$J$1000, 3, FALSE)) -> 0 | C14: =IF(ISBLANK($A14), "", VLOOKUP($A14, 入力シート!$A$7:$J$1000, 4, FALSE)) -> 0 | D14: =IF(ISBLANK($A14), "", VLOOKUP($A14, 入力シート!$A$7:$J$1000, 6, FALSE)) -> 0 | E14: =IF(ISBLANK($A14), "", VLOOKUP($A14, 入力シート!$A$7:$J$1000, 7, FALSE)) -> 0 | F14: =IF(ISBLANK($A14), "", VLOOKUP($A14, 入力シート!$A$7:$J$1000, 9, FALSE)) -> 0 | G14: =IF(ISBLANK($A14), "", VLOOKUP($A14, 入力シート!$A$7:$J$1000, 8, FALSE)) -> 0

Sheet 所有者調書(杉並)
B1: 土 地 所 有 者 調 書
F2: =TODAY() -> 45779
F3: 調査者名 土地家屋調査士 岡藤央樹 印 | L3: 調査者名 土地家屋調査士 岡藤央樹 印
B4: 土地所在 | C4: 地番 | D4: 地目 | E4: 地積 (㎡) | F4: 登記 年月日 | G4: 所有者名 | H4: 登記事項の住所 | L4: 調査者名 土地家屋調査士 笹生昌史 印
H5: 現在の住所
A6: 1 | B6: =IF(ISBLANK($A6), "", VLOOKUP($A6, 入力シート!$A$7:$J$1000, 3, FALSE)) -> #REF! | C6: =IF(ISBLANK($A6), "", VLOOKUP($A6, 入力シート!$A$7:$J$1000, 4, FALSE)) -> #REF! | D6: =IF(ISBLANK($A6), "", VLOOKUP($A6, 入力シート!$A$7:$J$1000, 6, FALSE)) -> #REF! | E6: =IF(ISBLANK($A6), "", VLOOKUP($A6, 入力シート!$A$7:$J$1000, 7, FALSE)) -> #REF! | F6: =IF(ISBLANK($A6), "", VLOOKUP($A6, 入力シート!$A$7:$J$1000, 10, FALSE)) -> #REF! | G6: =IF(ISBLANK($A6), "", VLOOKUP($A6, 入力シート!$A$7:$J$1000, 9, FALSE)) -> #REF! | H6: =IF(ISBLANK($A6), "", VLOOKUP($A6, 入力シート!$A$7:$J$1000, 8, FALSE)) -> #REF!
A8: 2 | B8: =IF(ISBLANK($A8), "", VLOOKUP($A8, 入力シート!$A$7:$J$1000, 3, FALSE)) -> #REF! | C8: =IF(ISBLANK($A8), "", VLOOKUP($A8, 入力シート!$A$7:$J$1000, 4, FALSE)) -> #REF! | D8: =IF(ISBLANK($A8), "", VLOOKUP($A8, 入力シート!$A$7:$J$1000, 6, FALSE)) -> #REF! | E8: =IF(ISBLANK($A8), "", VLOOKUP($A8, 入力シート!$A$7:$J$1000, 7, FALSE)) -> #REF! | F8: =IF(ISBLANK($A8), "", VLOOKUP($A8, 入力シート!$A$7:$J$1000, 10, FALSE)) -> #REF! | G8: =IF(ISBLANK($A8), "", VLOOKUP($A8, 入力シート!$A$7:$J$1000, 9, FALSE)) -> #REF! | H8: =IF(ISBLANK($A8), "", VLOOKUP($A8, 入力シート!$A$7:$J$1000, 8, FALSE)) -> #REF!
A10: 3 | B10: =IF(ISBLANK($A10), "", VLOOKUP($A10, 入力シート!$A$7:$J$1000, 3, FALSE)) -> #REF! | C10: =IF(ISBLANK($A10), "", VLOOKUP($A10, 入力シート!$A$7:$J$1000, 4, FALSE)) -> #REF! | D10: =IF(ISBLANK($A10), "", VLOOKUP($A10, 入力シート!$A$7:$J$1000, 6, FALSE)) -> #REF! | E10: =IF(ISBLANK($A10), "", VLOOKUP($A10, 入力シート!$A$7:$J$1000, 7, FALSE)) -> #REF! | F10: =IF(ISBLANK($A10), "", VLOOKUP($A10, 入力シート!$A$7:$J$1000, 10, FALSE)) -> #REF! | G10: =IF(ISBLANK($A10), "", VLOOKUP($A10, 入力シート!$A$7:$J$1000, 9, FALSE)) -> #REF! | H10: =IF(ISBLANK($A10), "", VLOOKUP($A10, 入力シート!$A$7:$J$1000, 8, FALSE)) -> #REF!
A12: 4 | B12: =IF(ISBLANK($A12), "", VLOOKUP($A12, 入力シート!$A$7:$J$1000, 3, FALSE)) -> #REF! | C12: =IF(ISBLANK($A12), "", VLOOKUP($A12, 入力シート!$A$7:$J$1000, 4, FALSE)) -> #REF! | D12: =IF(ISBLANK($A12), "", VLOOKUP($A12, 入力シート!$A$7:$J$1000, 6, FALSE)) -> #REF! | E12: =IF(ISBLANK($A12), "", VLOOKUP($A12, 入力シート!$A$7:$J$1000, 7, FALSE)) -> #REF! | F12: =IF(ISBLANK($A12), "", VLOOKUP($A12, 入力シート!$A$7:$J$1000, 10, FALSE)) -> #REF! | G12: =IF(ISBLANK($A12), "", VLOOKUP($A12, 入力シート!$A$7:$J$1000, 9, FALSE)) -> #REF! | H12: =IF(ISBLANK($A12), "", VLOOKUP($A12, 入力シート!$A$7:$J$1000, 8, FALSE)) -> #REF!
A14: 5 | B14: =IF(ISBLANK($A14), "", VLOOKUP($A14, 入力シート!$A$7:$J$1000, 3, FALSE)) -> #REF! | C14: =IF(ISBLANK($A14), "", VLOOKUP($A14, 入力シート!$A$7:$J$1000, 4, FALSE)) -> #REF! | D14: =IF(ISBLANK($A14), "", VLOOKUP($A14, 入力シート!$A$7:$J$1000, 6, FALSE)) -> #REF! | E14: =IF(ISBLANK($A14), "", VLOOKUP($A14, 入力シート!$A$7:$J$1000, 7, FALSE)) -> #REF! | F14: =IF(ISBLANK($A14), "", VLOOKUP($A14, 入力シート!$A$7:$J$1000, 10, FALSE)) -> #REF! | G14: =IF(ISBLANK($A14), "", VLOOKUP($A14, 入力シート!$A$7:$J$1000, 9, FALSE)) -> #REF! | H14: =IF(ISBLANK($A14), "", VLOOKUP($A14, 入力シート!$A$7:$J$1000, 8, FALSE)) -> #REF!
